Workbook

Sheet Data
D8: Month | E8: 2003 | F8: 2004 | G8: 2005 | H8: 2006 | I8: 2007 | J8: 2008 | K8: 2009 | L8: 2010 | M8: 2011 | N8: 2012 | O8: Sparkline
C9: I | D9: January | F9: 5907 | G9: 7408 | H9: 9404 | I9: 10419 | J9: 9750 | K9: 9438 | L9: 15925 | M9: 19430 | N9: 17950
D10: February | F10: 6386 | G10: 7493 | H10: 8613 | I10: 8801 | J10: 8477 | K10: 8487 | L10: 13532 | M10: 17534 | N10: 13534
D11: March | F11: 9085 | G11: 8541 | H11: 9425 | I11: 8631 | J11: 9814 | K11: 10609 | L11: 14648 | M11: 17822 | N11: 15054
C12: II | D12: April | E12: 4698 | F12: 6492 | G12: 8029 | H12: 10905 | I12: 9682 | J12: 10684 | K12: 11282 | L12: 15697 | M12: 17740
D13: May | E13: 4605 | F13: 6832 | G13: 8650 | H13: 9842 | I13: 9052 | J13: 11693 | K13: 12870 | L13: 16653 | M13: 17952
D14: June | E14: 4859 | F14: 8867 | G14: 9960 | H14: 12259 | I14: 11477 | J14: 14439 | K14: 17811 | L14: 15411 | M14: 21552
C15: III | D15: July | E15: 4136 | F15: 4998 | G15: 7152 | H15: 9285 | I15: 8242 | J15: 9081 | K15: 12128 | L15: 13534 | M15: 15699
D16: August | E16: 3872 | F16: 5305 | G16: 7322 | H16: 7950 | I16: 7674 | J16: 9781 | K16: 10161 | L16: 12454 | M16: 15059
D17: September | E17: 5938 | F17: 7618 | G17: 9239 | H17: 11482 | I17: 10339 | J17: 10307 | K17: 16359 | L17: 16300 | M17: 23508
C18: IV | D18: October | E18: 8790 | F18: 11443 | G18: 14123 | H18: 15817 | I18: 13919 | J18: 14800 | K18: 17796 | L18: 23378 | M18: 30519
D19: November | E19: 6825 | F19: 8716 | G19: 9566 | H19: 10288 | I19: 10531 | J19: 7960 | K19: 11604 | L19: 16975 | M19: 16175
D20: December | E20: 4858 | F20: 6119 | G20: 7341 | H20: 8743 | I20: 8435 | J20: 6858 | K20: 11517 | L20: 15135 | M20: 15315

Sheet Month
A1: Year | B1: Month | C1: Industry | D1: MMFD
A2: 2003 | B2: April | C2: 10281 | D2: 4698
B3: May | C3: 11683 | D3: 4605
B4: June | C4: 14042 | D4: 4859
B5: July | C5: 10283 | D5: 4136
B6: August | C6: 9522 | D6: 3872
B7: September | C7: 14263 | D7: 5938
B8: October | C8: 20264 | D8: 8790
B9: November | C9: 15778 | D9: 6825
B10: December | C10: 12758 | D10: 4858
A11: 2004 | B11: January | C11: 14297 | D11: 5907
B12: February | C12: 17521 | D12: 6386
B13: March | C13: 24773 | D13: 9085
B14: April | C14: 15714 | D14: 6492
B15: May | C15: 17352 | D15: 6832
B16: June | C16: 20901 | D16: 8867
B17: July | C17: 12065 | D17: 4998
B18: August | C18: 13452 | D18: 5305
B19: September | C19: 22018 | D19: 7618
B20: October | C20: 27631 | D20: 11443
B21: November | C21: 21799 | D21: 8716
B22: December | C22: 16209 | D22: 6119
A23: 2005 | B23: January | C23: 16249 | D23: 7408
B24: February | C24: 18867 | D24: 7493
B25: March | C25: 23857 | D25: 8541
B26: April | C26: 16828 | D26: 8029
B27: May | C27: 19062 | D27: 8650
B28: June | C28: 22724 | D28: 9960
B29: July | C29: 15320 | D29: 7152
B30: August | C30: 16936 | D30: 7322
B31: September | C31: 21986 | D31: 9239
B32: October | C32: 30998 | D32: 14123
B33: November | C33: 22359 | D33: 9566
B34: December | C34: 20860 | D34: 7341
A35: 2006 | B35: January | C35: 24057 | D35: 9404
B36: February | C36: 23506 | D36: 8613
B37: March | C37: 27985 | D37: 9425
B38: April | C38: 24416 | D38: 10905
B39: May | C39: 24262 | D39: 9842
B40: June | C40: 29924 | D40: 12259
...

Sheet NAive
A1: #Month | B1: Year | C1: Month | D1: Demand | E1: Forecast | G1: Forecast error | H1: Absolute value | I1: MSE | J1: MAD | K1: APE | L1: MAPE | M1: Bias | N1: TS
A2: 1 | B2: 2003 | C2: April | D2: 4698
A3: 2 | C3: May | D3: 4605 | E3: =D2 -> 4698 | G3: =E3-D3 -> 93 | H3: =ABS(G3) -> 93 | I3: =SUMSQ($G$3:G3)/(A3-1) -> 8649 | J3: =SUM($H$3:H3)/(A3-1) -> 93 | K3: =H3/D3 -> 0.02019544 | L3: =SUM($K$3:K3)/(A3-1) -> 0.02019544 | M3: =SUM($G$3:G3) -> 93 | N3: =M3/J3 -> 1
A4: 3 | C4: June | D4: 4859 | E4: =D3 -> 4605 | G4: =E4-D4 -> -254 | H4: =ABS(G4) -> 254 | I4: =SUMSQ($G$3:G4)/(A4-1) -> 36582.5 | J4: =SUM($H$3:H4)/(A4-1) -> 173.5 | K4: =H4/D4 -> 0.05227413 | L4: =SUM($K$3:K4)/(A4-1) -> 0.036234785 | M4: =SUM($G$3:G4) -> -161 | N4: =M4/J4 -> -0.92795389
A5: 4 | C5: July | D5: 4136 | E5: =D4 -> 4859 | G5: =E5-D5 -> 723 | H5: =ABS(G5) -> 723 | I5: =SUMSQ($G$3:G5)/(A5-1) -> 198631.33 | J5: =SUM($H$3:H5)/(A5-1) -> 356.66667 | K5: =H5/D5 -> 0.17480658 | L5: =SUM($K$3:K5)/(A5-1) -> 0.082425382 | M5: =SUM($G$3:G5) -> 562 | N5: =M5/J5 -> 1.5757009
A6: 5 | C6: August | D6: 3872 | E6: =D5 -> 4136 | G6: =E6-D6 -> 264 | H6: =ABS(G6) -> 264 | I6: =SUMSQ($G$3:G6)/(A6-1) -> 166397.5 | J6: =SUM($H$3:H6)/(A6-1) -> 333.5 | K6: =H6/D6 -> 0.068181818 | L6: =SUM($K$3:K6)/(A6-1) -> 0.078864491 | M6: =SUM($G$3:G6) -> 826 | N6: =M6/J6 -> 2.4767616
A7: 6 | C7: September | D7: 5938 | E7: =D6 -> 3872 | G7: =E7-D7 -> -2066 | H7: =ABS(G7) -> 2066 | I7: =SUMSQ($G$3:G7)/(A7-1) -> 986789.2 | J7: =SUM($H$3:H7)/(A7-1) -> 680 | K7: =H7/D7 -> 0.3479286 | L7: =SUM($K$3:K7)/(A7-1) -> 0.13267731 | M7: =SUM($G$3:G7) -> -1240 | N7: =M7/J7 -> -1.8235294
A8: 7 | C8: October | D8: 8790 | E8: =D7 -> 5938 | G8: =E8-D8 -> -2852 | H8: =ABS(G8) -> 2852 | I8: =SUMSQ($G$3:G8)/(A8-1) -> 2177975 | J8: =SUM($H$3:H8)/(A8-1) -> 1042 | K8: =H8/D8 -> 0.32445961 | L8: =SUM($K$3:K8)/(A8-1) -> 0.16464103 | M8: =SUM($G$3:G8) -> -4092 | N8: =M8/J8 -> -3.9270633
A9: 8 | C9: November | D9: 6825 | E9: =D8 -> 8790 | G9: =E9-D9 -> 1965 | H9: =ABS(G9) -> 1965 | I9: =SUMSQ($G$3:G9)/(A9-1) -> 2418439.3 | J9: =SUM($H$3:H9)/(A9-1) -> 1173.8571 | K9: =H9/D9 -> 0.28791209 | L9: =SUM($K$3:K9)/(A9-1) -> 0.18225118 | M9: =SUM($G$3:G9) -> -2127 | N9: =M9/J9 -> -1.8119752
A10: 9 | C10: December | D10: 4858 | E10: =D9 -> 6825 | G10: =E10-D10 -> 1967 | H10: =ABS(G10) -> 1967 | I10: =SUMSQ($G$3:G10)/(A10-1) -> 2599770.5 | J10: =SUM($H$3:H10)/(A10-1) -> 1273 | K10: =H10/D10 -> 0.40489914 | L10: =SUM($K$3:K10)/(A10-1) -> 0.21008217 | M10: =SUM($G$3:G10) -> -160 | N10: =M10/J10 -> -0.12568735
A11: 10 | B11: 2004 | C11: January | D11: 5907 | E11: =D10 -> 4858 | G11: =E11-D11 -> -1049 | H11: =ABS(G11) -> 1049 | I11: =SUMSQ($G$3:G11)/(A11-1) -> 2433173.9 | J11: =SUM($H$3:H11)/(A11-1) -> 1248.1111 | K11: =H11/D11 -> 0.17758592 | L11: =SUM($K$3:K11)/(A11-1) -> 0.20647148 | M11: =SUM($G$3:G11) -> -1209 | N11: =M11/J11 -> -0.96866376
A12: 11 | C12: February | D12: 6386 | E12: =D11 -> 5907 | G12: =E12-D12 -> -479 | H12: =ABS(G12) -> 479 | I12: =SUMSQ($G$3:G12)/(A12-1) -> 2212800.6 | J12: =SUM($H$3:H12)/(A12-1) -> 1171.2 | K12: =H12/D12 -> 0.07500783 | L12: =SUM($K$3:K12)/(A12-1) -> 0.19332511 | M12: =SUM($G$3:G12) -> -1688 | N12: =M12/J12 -> -1.4412568
A13: 12 | C13: March | D13: 9085 | E13: =D12 -> 6386 | G13: =E13-D13 -> -2699 | H13: =ABS(G13) -> 2699 | I13: =SUMSQ($G$3:G13)/(A13-1) -> 2673873.4 | J13: =SUM($H$3:H13)/(A13-1) -> 1310.0909 | K13: =H13/D13 -> 0.2970831 | L13: =SUM($K$3:K13)/(A13-1) -> 0.20275766 | M13: =SUM($G$3:G13) -> -4387 | N13: =M13/J13 -> -3.3486226
A14: 13 | C14: April | D14: 6492 | E14: =D13 -> 9085 | G14: =E14-D14 -> 2593 | H14: =ABS(G14) -> 2593 | I14: =SUMSQ($G$3:G14)/(A14-1) -> 3011354.7 | J14: =SUM($H$3:H14)/(A14-1) -> 1417 | K14: =H14/D14 -> 0.39941466 | L14: =SUM($K$3:K14)/(A14-1) -> 0.21914574 | M14: =SUM($G$3:G14) -> -1794 | N14: =M14/J14 -> -1.266055
A15: 14 | C15: May | D15: 6832 | E15: =D14 -> 6492 | G15: =E15-D15 -> -340 | H15: =ABS(G15) -> 340 | I15: =SUMSQ($G$3:G15)/(A15-1) -> 2788604.3 | J15: =SUM($H$3:H15)/(A15-1) -> 1334.1538 | K15: =H15/D15 -> 0.049765808 | L15: =SUM($K$3:K15)/(A15-1) -> 0.20611652 | M15: =SUM($G$3:G15) -> -2134 | N15: =M15/J15 -> -1.5995157
A16: 15 | C16: June | D16: 8867 | E16: =D15 -> 6832 | G16: =E16-D16 -> -2035 | H16: =ABS(G16) -> 2035 | I16: =SUMSQ($G$3:G16)/(A16-1) -> 2885220.1 | J16: =SUM($H$3:H16)/(A16-1) -> 1384.2143 | K16: =H16/D16 -> 0.22950265 | L16: =SUM($K$3:K16)/(A16-1) -> 0.20778695 | M16: =SUM($G$3:G16) -> -4169 | N16: =M16/J16 -> -3.0118169
A17: 16 | C17: July | D17: 4998 | E17: =D16 -> 8867 | G17: =E17-D17 -> 3869 | H17: =ABS(G17) -> 3869 | I17: =SUMSQ($G$3:G17)/(A17-1) -> 3690816.1 | J17: =SUM($H$3:H17)/(A17-1) -> 1549.8667 | K17: =H17/D17 -> 0.77410964 | L17: =SUM($K$3:K17)/(A17-1) -> 0.2455418 | M17: =SUM($G$3:G17) -> -300 | N17: =M17/J17 -> -0.19356504
A18: 17 | C18: August | D18: 5305 | E18: =D17 -> 4998 | G18: =E18-D18 -> -307 | H18: =ABS(G18) -> 307 | I18: =SUMSQ($G$3:G18)/(A18-1) -> 3466030.7 | J18: =SUM($H$3:H18)/(A18-1) -> 1472.1875 | K18: =H18/D18 -> 0.057869934 | L18: =SUM($K$3:K18)/(A18-1) -> 0.23381231 | M18: =SUM($G$3:G18) -> -607 | N18: =M18/J18 -> -0.41231161
A19: 18 | C19: September | D19: 7618 | E19: =D18 -> 5305 | G19: =E19-D19 -> -2313 | H19: =ABS(G19) -> 2313 | I19: =SUMSQ($G$3:G19)/(A19-1) -> 3576850.6 | J19: =SUM($H$3:H19)/(A19-1) -> 1521.6471 | K19: =H19/D19 -> 0.303623 | L19: =SUM($K$3:K19)/(A19-1) -> 0.23791882 | M19: =SUM($G$3:G19) -> -2920 | N19: =M19/J19 -> -1.9189732
A20: 19 | C20: October | D20: 11443 | E20: =D19 -> 7618 | G20: =E20-D20 -> -3825 | H20: =ABS(G20) -> 3825 | I20: =SUMSQ($G$3:G20)/(A20-1) -> 4190949.2 | J20: =SUM($H$3:H20)/(A20-1) -> 1649.6111 | K20: =H20/D20 -> 0.33426549 | L20: =SUM($K$3:K20)/(A20-1) -> 0.24327141 | M20: =SUM($G$3:G20) -> -6745 | N20: =M20/J20 -> -4.0888425
A21: 20 | C21: November | D21: 8716 | E21: =D20 -> 11443 | G21: =E21-D21 -> 2727 | H21: =ABS(G21) -> 2727 | I21: =SUMSQ($G$3:G21)/(A21-1) -> 4361769.2 | J21: =SUM($H$3:H21)/(A21-1) -> 1706.3158 | K21: =H21/D21 -> 0.31287288 | L21: =SUM($K$3:K21)/(A21-1) -> 0.24693465 | M21: =SUM($G$3:G21) -> -4018 | N21: =M21/J21 -> -2.354781
A22: 21 | C22: December | D22: 6119 | E22: =D21 -> 8716 | G22: =E22-D22 -> 2597 | H22: =ABS(G22) -> 2597 | I22: =SUMSQ($G$3:G22)/(A22-1) -> 4480901.2 | J22: =SUM($H$3:H22)/(A22-1) -> 1750.85 | K22: =H22/D22 -> 0.42441575 | L22: =SUM($K$3:K22)/(A22-1) -> 0.2558087 | M22: =SUM($G$3:G22) -> -1421 | N22: =M22/J22 -> -0.81160579
A23: 22 | B23: 2005 | C23: January | D23: 7408 | E23: =D22 -> 6119 | G23: =E23-D23 -> -1289 | H23: =ABS(G23) -> 1289 | I23: =SUMSQ($G$3:G23)/(A23-1) -> 4346645 | J23: =SUM($H$3:H23)/(A23-1) -> 1728.8571 | K23: =H23/D23 -> 0.17400108 | L23: =SUM($K$3:K23)/(A23-1) -> 0.2519131 | M23: =SUM($G$3:G23) -> -2710 | N23: =M23/J23 -> -1.5675095
A24: 23 | C24: February | D24: 7493 | E24: =D23 -> 7408 | G24: =E24-D24 -> -85 | H24: =ABS(G24) -> 85 | I24: =SUMSQ($G$3:G24)/(A24-1) -> 4149398.6 | J24: =SUM($H$3:H24)/(A24-1) -> 1654.1364 | K24: =H24/D24 -> 0.011343921 | L24: =SUM($K$3:K24)/(A24-1) -> 0.24097814 | M24: =SUM($G$3:G24) -> -2795 | N24: =M24/J24 -> -1.6897035
A25: 24 | C25: March | D25: 8541 | E25: =D24 -> 7493 | G25: =E25-D25 -> -1048 | H25: =ABS(G25) -> 1048 | I25: =SUMSQ($G$3:G25)/(A25-1) -> 4016742.3 | J25: =SUM($H$3:H25)/(A25-1) -> 1627.7826 | K25: =H25/D25 -> 0.12270226 | L25: =SUM($K$3:K25)/(A25-1) -> 0.23583571 | M25: =SUM($G$3:G25) -> -3843 | N25: =M25/J25 -> -2.3608804
A26: 25 | C26: April | D26: 8029 | E26: =D25 -> 8541 | G26: =E26-D26 -> 512 | H26: =ABS(G26) -> 512 | I26: =SUMSQ($G$3:G26)/(A26-1) -> 3860300.7 | J26: =SUM($H$3:H26)/(A26-1) -> 1581.2917 | K26: =H26/D26 -> 0.063768838 | L26: =SUM($K$3:K26)/(A26-1) -> 0.22866626 | M26: =SUM($G$3:G26) -> -3331 | N26: =M26/J26 -> -2.1065058
A27: 26 | C27: May | D27: 8650 | E27: =D26 -> 8029 | G27: =E27-D27 -> -621 | H27: =ABS(G27) -> 621 | I27: =SUMSQ($G$3:G27)/(A27-1) -> 3721314.3 | J27: =SUM($H$3:H27)/(A27-1) -> 1542.88 | K27: =H27/D27 -> 0.071791908 | L27: =SUM($K$3:K27)/(A27-1) -> 0.22239128 | M27: =SUM($G$3:G27) -> -3952 | N27: =M27/J27 -> -2.5614435
A28: 27 | C28: June | D28: 9960 | E28: =D27 -> 8650 | G28: =E28-D28 -> -1310 | H28: =ABS(G28) -> 1310 | I28: =SUMSQ($G$3:G28)/(A28-1) -> 3644190.7 | J28: =SUM($H$3:H28)/(A28-1) -> 1533.9231 | K28: =H28/D28 -> 0.1315261 | L28: =SUM($K$3:K28)/(A28-1) -> 0.21889647 | M28: =SUM($G$3:G28) -> -5262 | N28: =M28/J28 -> -3.4304197
A29: 28 | C29: July | D29: 7152 | E29: =D28 -> 9960 | G29: =E29-D29 -> 2808 | H29: =ABS(G29) -> 2808 | I29: =SUMSQ($G$3:G29)/(A29-1) -> 3801252.7 | J29: =SUM($H$3:H29)/(A29-1) -> 1581.1111 | K29: =H29/D29 -> 0.39261745 | L29: =SUM($K$3:K29)/(A29-1) -> 0.22533058 | M29: =SUM($G$3:G29) -> -2454 | N29: =M29/J29 -> -1.5520731
A30: 29 | C30: August | D30: 7322 | E30: =D29 -> 7152 | G30: =E30-D30 -> -170 | H30: =ABS(G30) -> 170 | I30: =SUMSQ($G$3:G30)/(A30-1) -> 3666525.8 | J30: =SUM($H$3:H30)/(A30-1) -> 1530.7143 | K30: =H30/D30 -> 0.0232177 | L30: =SUM($K$3:K30)/(A30-1) -> 0.21811226 | M30: =SUM($G$3:G30) -> -2624 | N30: =M30/J30 -> -1.7142324
A31: 30 | C31: September | D31: 9239 | E31: =D30 -> 7322 | G31: =E31-D31 -> -1917 | H31: =ABS(G31) -> 1917 | I31: =SUMSQ($G$3:G31)/(A31-1) -> 3666814.2 | J31: =SUM($H$3:H31)/(A31-1) -> 1544.0345 | K31: =H31/D31 -> 0.20748999 | L31: =SUM($K$3:K31)/(A31-1) -> 0.21774598 | M31: =SUM($G$3:G31) -> -4541 | N31: =M31/J31 -> -2.9409965
A32: 31 | C32: October | D32: 14123 | E32: =D31 -> 9239 | G32: =E32-D32 -> -4884 | H32: =ABS(G32) -> 4884 | I32: =SUMSQ($G$3:G32)/(A32-1) -> 4339702.2 | J32: =SUM($H$3:H32)/(A32-1) -> 1655.3667 | K32: =H32/D32 -> 0.34581888 | L32: =SUM($K$3:K32)/(A32-1) -> 0.22201507 | M32: =SUM($G$3:G32) -> -9425 | N32: =M32/J32 -> -5.6936026
A33: 32 | C33: November | D33: 9566 | E33: =D32 -> 14123 | G33: =E33-D33 -> 4557 | H33: =ABS(G33) -> 4557 | I33: =SUMSQ($G$3:G33)/(A33-1) -> 4869590.8 | J33: =SUM($H$3:H33)/(A33-1) -> 1748.9677 | K33: =H33/D33 -> 0.47637466 | L33: =SUM($K$3:K33)/(A33-1) -> 0.23022022 | M33: =SUM($G$3:G33) -> -4868 | N33: =M33/J33 -> -2.7833561
A34: 33 | C34: December | D34: 7341 | E34: =D33 -> 9566 | G34: =E34-D34 -> 2225 | H34: =ABS(G34) -> 2225 | I34: =SUMSQ($G$3:G34)/(A34-1) -> 4872123.2 | J34: =SUM($H$3:H34)/(A34-1) -> 1763.8438 | K34: =H34/D34 -> 0.30309222 | L34: =SUM($K$3:K34)/(A34-1) -> 0.23249747 | M34: =SUM($G$3:G34) -> -2643 | N34: =M34/J34 -> -1.498432
A35: 34 | B35: 2006 | C35: January | D35: 9404 | E35: =D34 -> 7341 | G35: =E35-D35 -> -2063 | H35: =ABS(G35) -> 2063 | I35: =SUMSQ($G$3:G35)/(A35-1) -> 4853451.8 | J35: =SUM($H$3:H35)/(A35-1) -> 1772.9091 | K35: =H35/D35 -> 0.21937473 | L35: =SUM($K$3:K35)/(A35-1) -> 0.23209981 | M35: =SUM($G$3:G35) -> -4706 | N35: =M35/J35 -> -2.6543944
A36: 35 | C36: February | D36: 8613 | E36: =D35 -> 9404 | G36: =E36-D36 -> 791 | H36: =ABS(G36) -> 791 | I36: =SUMSQ($G$3:G36)/(A36-1) -> 4729105.6 | J36: =SUM($H$3:H36)/(A36-1) -> 1744.0294 | K36: =H36/D36 -> 0.091837919 | L36: =SUM($K$3:K36)/(A36-1) -> 0.22797446 | M36: =SUM($G$3:G36) -> -3915 | N36: =M36/J36 -> -2.2448016
A37: 36 | C37: March | D37: 9425 | E37: =D36 -> 8613 | G37: =E37-D37 -> -812 | H37: =ABS(G37) -> 812 | I37: =SUMSQ($G$3:G37)/(A37-1) -> 4612826.7 | J37: =SUM($H$3:H37)/(A37-1) -> 1717.4 | K37: =H37/D37 -> 0.086153846 | L37: =SUM($K$3:K37)/(A37-1) -> 0.22392244 | M37: =SUM($G$3:G37) -> -4727 | N37: =M37/J37 -> -2.7524164
A38: 37 | C38: April | D38: 10905 | E38: =D37 -> 9425 | G38: =E38-D38 -> -1480 | H38: =ABS(G38) -> 1480 | I38: =SUMSQ($G$3:G38)/(A38-1) -> 4545537.1 | J38: =SUM($H$3:H38)/(A38-1) -> 1710.8056 | K38: =H38/D38 -> 0.13571756 | L38: =SUM($K$3:K38)/(A38-1) -> 0.22147231 | M38: =SUM($G$3:G38) -> -6207 | N38: =M38/J38 -> -3.6281154
A39: 38 | C39: May | D39: 9842 | E39: =D38 -> 10905 | G39: =E39-D39 -> 1063 | H39: =ABS(G39) -> 1063 | I39: =SUMSQ($G$3:G39)/(A39-1) -> 4453224.4 | J39: =SUM($H$3:H39)/(A39-1) -> 1693.2973 | K39: =H39/D39 -> 0.1080065 | L39: =SUM($K$3:K39)/(A39-1) -> 0.21840567 | M39: =SUM($G$3:G39) -> -5144 | N39: =M39/J39 -> -3.0378599
A40: 39 | C40: June | D40: 12259 | E40: =D39 -> 9842 | G40: =E40-D40 -> -2417 | H40: =ABS(G40) -> 2417 | I40: =SUMSQ($G$3:G40)/(A40-1) -> 4489768.2 | J40: =SUM($H$3:H40)/(A40-1) -> 1712.3421 | K40: =H40/D40 -> 0.19716127 | L40: =SUM($K$3:K40)/(A40-1) -> 0.2178466 | M40: =SUM($G$3:G40) -> -7561 | N40: =M40/J40 -> -4.4155896
...

Sheet MA (3m)
A2: #Month | B2: Year | C2: Month | D2: Demand | E2: 3 Month Moving Average | G2: Forecast error Et | H2: Absolute value At | I2: MSE | J2: MAD | K2: APE | L2: MAPE | M2: Bias | N2: TS
A3: 1 | B3: 2003 | C3: April | D3: 4698
A4: 2 | C4: May | D4: 4605
A5: 3 | C5: June | D5: 4859
A6: 4 | C6: July | D6: 4136 | E6: =SUM(D3:D5)/3 -> 4720.6667 | G6: =D6-E6 -> -584.66667 | H6: =ABS(G6) -> 584.66667 | I6: =SUMSQ($G$6:G6)/(A6-3) -> 341835.11 | J6: =SUM($H$6:H6)/(A6-3) -> 584.66667 | K6: =H6/D6 -> 0.14136041 | L6: =SUM($K$6:K6)/(A6-3) -> 0.14136041 | M6: =SUM($G$6:G6) -> -584.66667 | N6: =M6/J6 -> -1
A7: 5 | C7: August | D7: 3872 | E7: =SUM(D4:D6)/3 -> 4533.3333 | G7: =D7-E7 -> -661.33333 | H7: =ABS(G7) -> 661.33333 | I7: =SUMSQ($G$6:G7)/(A7-3) -> 389598.44 | J7: =SUM($H$6:H7)/(A7-3) -> 623 | K7: =H7/D7 -> 0.1707989 | L7: =SUM($K$6:K7)/(A7-3) -> 0.15607966 | M7: =SUM($G$6:G7) -> -1246 | N7: =M7/J7 -> -2
A8: 6 | C8: September | D8: 5938 | E8: =SUM(D5:D7)/3 -> 4289 | G8: =D8-E8 -> 1649 | H8: =ABS(G8) -> 1649 | I8: =SUMSQ($G$6:G8)/(A8-3) -> 1166132.6 | J8: =SUM($H$6:H8)/(A8-3) -> 965 | K8: =H8/D8 -> 0.27770293 | L8: =SUM($K$6:K8)/(A8-3) -> 0.19662075 | M8: =SUM($G$6:G8) -> 403 | N8: =M8/J8 -> 0.41761658
A9: 7 | C9: October | D9: 8790 | E9: =SUM(D6:D8)/3 -> 4648.6667 | G9: =D9-E9 -> 4141.3333 | H9: =ABS(G9) -> 4141.3333 | I9: =SUMSQ($G$6:G9)/(A9-3) -> 5162259.9 | J9: =SUM($H$6:H9)/(A9-3) -> 1759.0833 | K9: =H9/D9 -> 0.47114145 | L9: =SUM($K$6:K9)/(A9-3) -> 0.26525092 | M9: =SUM($G$6:G9) -> 4544.3333 | N9: =M9/J9 -> 2.5833531
A10: 8 | C10: November | D10: 6825 | E10: =SUM(D7:D9)/3 -> 6200 | G10: =D10-E10 -> 625 | H10: =ABS(G10) -> 625 | I10: =SUMSQ($G$6:G10)/(A10-3) -> 4207932.9 | J10: =SUM($H$6:H10)/(A10-3) -> 1532.2667 | K10: =H10/D10 -> 0.091575092 | L10: =SUM($K$6:K10)/(A10-3) -> 0.23051576 | M10: =SUM($G$6:G10) -> 5169.3333 | N10: =M10/J10 -> 3.3736512
A11: 9 | C11: December | D11: 4858 | E11: =SUM(D8:D10)/3 -> 7184.3333 | G11: =D11-E11 -> -2326.3333 | H11: =ABS(G11) -> 2326.3333 | I11: =SUMSQ($G$6:G11)/(A11-3) -> 4408581.9 | J11: =SUM($H$6:H11)/(A11-3) -> 1664.6111 | K11: =H11/D11 -> 0.47886647 | L11: =SUM($K$6:K11)/(A11-3) -> 0.27190754 | M11: =SUM($G$6:G11) -> 2843 | N11: =M11/J11 -> 1.7079064
A12: 10 | B12: 2004 | C12: January | D12: 5907 | E12: =SUM(D9:D11)/3 -> 6824.3333 | G12: =D12-E12 -> -917.33333 | H12: =ABS(G12) -> 917.33333 | I12: =SUMSQ($G$6:G12)/(A12-3) -> 3898998.8 | J12: =SUM($H$6:H12)/(A12-3) -> 1557.8571 | K12: =H12/D12 -> 0.15529598 | L12: =SUM($K$6:K12)/(A12-3) -> 0.25524875 | M12: =SUM($G$6:G12) -> 1925.6667 | N12: =M12/J12 -> 1.2360996
A13: 11 | C13: February | D13: 6386 | E13: =SUM(D10:D12)/3 -> 5863.3333 | G13: =D13-E13 -> 522.66667 | H13: =ABS(G13) -> 522.66667 | I13: =SUMSQ($G$6:G13)/(A13-3) -> 3445771.5 | J13: =SUM($H$6:H13)/(A13-3) -> 1428.4583 | K13: =H13/D13 -> 0.081845704 | L13: =SUM($K$6:K13)/(A13-3) -> 0.23357337 | M13: =SUM($G$6:G13) -> 2448.3333 | N13: =M13/J13 -> 1.713969
A14: 12 | C14: March | D14: 9085 | E14: =SUM(D11:D13)/3 -> 5717 | G14: =D14-E14 -> 3368 | H14: =ABS(G14) -> 3368 | I14: =SUMSQ($G$6:G14)/(A14-3) -> 4323288.5 | J14: =SUM($H$6:H14)/(A14-3) -> 1643.963 | K14: =H14/D14 -> 0.37072097 | L14: =SUM($K$6:K14)/(A14-3) -> 0.24881199 | M14: =SUM($G$6:G14) -> 5816.3333 | N14: =M14/J14 -> 3.5379954
A15: 13 | C15: April | D15: 6492 | E15: =SUM(D12:D14)/3 -> 7126 | G15: =D15-E15 -> -634 | H15: =ABS(G15) -> 634 | I15: =SUMSQ($G$6:G15)/(A15-3) -> 3931155.2 | J15: =SUM($H$6:H15)/(A15-3) -> 1542.9667 | K15: =H15/D15 -> 0.097658657 | L15: =SUM($K$6:K15)/(A15-3) -> 0.23369666 | M15: =SUM($G$6:G15) -> 5182.3333 | N15: =M15/J15 -> 3.3586813
A16: 14 | C16: May | D16: 6832 | E16: =SUM(D13:D15)/3 -> 7321 | G16: =D16-E16 -> -489 | H16: =ABS(G16) -> 489 | I16: =SUMSQ($G$6:G16)/(A16-3) -> 3595515.8 | J16: =SUM($H$6:H16)/(A16-3) -> 1447.1515 | K16: =H16/D16 -> 0.071574941 | L16: =SUM($K$6:K16)/(A16-3) -> 0.21895832 | M16: =SUM($G$6:G16) -> 4693.3333 | N16: =M16/J16 -> 3.2431527
A17: 15 | C17: June | D17: 8867 | E17: =SUM(D14:D16)/3 -> 7469.6667 | G17: =D17-E17 -> 1397.3333 | H17: =ABS(G17) -> 1397.3333 | I17: =SUMSQ($G$6:G17)/(A17-3) -> 3458601.1 | J17: =SUM($H$6:H17)/(A17-3) -> 1443 | K17: =H17/D17 -> 0.15758806 | L17: =SUM($K$6:K17)/(A17-3) -> 0.21384413 | M17: =SUM($G$6:G17) -> 6090.6667 | N17: =M17/J17 -> 4.2208362
A18: 16 | C18: July | D18: 4998 | E18: =SUM(D15:D17)/3 -> 7397 | G18: =D18-E18 -> -2399 | H18: =ABS(G18) -> 2399 | I18: =SUMSQ($G$6:G18)/(A18-3) -> 3635262.7 | J18: =SUM($H$6:H18)/(A18-3) -> 1516.5385 | K18: =H18/D18 -> 0.479992 | L18: =SUM($K$6:K18)/(A18-3) -> 0.23431704 | M18: =SUM($G$6:G18) -> 3691.6667 | N18: =M18/J18 -> 2.4342717
A19: 17 | C19: August | D19: 5305 | E19: =SUM(D16:D18)/3 -> 6899 | G19: =D19-E19 -> -1594 | H19: =ABS(G19) -> 1594 | I19: =SUMSQ($G$6:G19)/(A19-3) -> 3557089.3 | J19: =SUM($H$6:H19)/(A19-3) -> 1522.0714 | K19: =H19/D19 -> 0.30047125 | L19: =SUM($K$6:K19)/(A19-3) -> 0.23904234 | M19: =SUM($G$6:G19) -> 2097.6667 | N19: =M19/J19 -> 1.3781657
A20: 18 | C20: September | D20: 7618 | E20: =SUM(D17:D19)/3 -> 6390 | G20: =D20-E20 -> 1228 | H20: =ABS(G20) -> 1228 | I20: =SUMSQ($G$6:G20)/(A20-3) -> 3420482.3 | J20: =SUM($H$6:H20)/(A20-3) -> 1502.4667 | K20: =H20/D20 -> 0.16119716 | L20: =SUM($K$6:K20)/(A20-3) -> 0.23385267 | M20: =SUM($G$6:G20) -> 3325.6667 | N20: =M20/J20 -> 2.2134712
A21: 19 | C21: October | D21: 11443 | E21: =SUM(D18:D20)/3 -> 5973.6667 | G21: =D21-E21 -> 5469.3333 | H21: =ABS(G21) -> 5469.3333 | I21: =SUMSQ($G$6:G21)/(A21-3) -> 5076302.6 | J21: =SUM($H$6:H21)/(A21-3) -> 1750.3958 | K21: =H21/D21 -> 0.47796324 | L21: =SUM($K$6:K21)/(A21-3) -> 0.24910958 | M21: =SUM($G$6:G21) -> 8795 | N21: =M21/J21 -> 5.0245778
A22: 20 | C22: November | D22: 8716 | E22: =SUM(D19:D21)/3 -> 8122 | G22: =D22-E22 -> 594 | H22: =ABS(G22) -> 594 | I22: =SUMSQ($G$6:G22)/(A22-3) -> 4798451.6 | J22: =SUM($H$6:H22)/(A22-3) -> 1682.3725 | K22: =H22/D22 -> 0.068150528 | L22: =SUM($K$6:K22)/(A22-3) -> 0.23846493 | M22: =SUM($G$6:G22) -> 9389 | N22: =M22/J22 -> 5.5808091
A23: 21 | C23: December | D23: 6119 | E23: =SUM(D20:D22)/3 -> 9259 | G23: =D23-E23 -> -3140 | H23: =ABS(G23) -> 3140 | I23: =SUMSQ($G$6:G23)/(A23-3) -> 5079626.5 | J23: =SUM($H$6:H23)/(A23-3) -> 1763.3519 | K23: =H23/D23 -> 0.51315574 | L23: =SUM($K$6:K23)/(A23-3) -> 0.25372553 | M23: =SUM($G$6:G23) -> 6249 | N23: =M23/J23 -> 3.5438191
A24: 22 | B24: 2005 | C24: January | D24: 7408 | E24: =SUM(D21:D23)/3 -> 8759.3333 | G24: =D24-E24 -> -1351.3333 | H24: =ABS(G24) -> 1351.3333 | I24: =SUMSQ($G$6:G24)/(A24-3) -> 4908388.4 | J24: =SUM($H$6:H24)/(A24-3) -> 1741.6667 | K24: =H24/D24 -> 0.18241541 | L24: =SUM($K$6:K24)/(A24-3) -> 0.24997236 | M24: =SUM($G$6:G24) -> 4897.6667 | N24: =M24/J24 -> 2.8120574
A25: 23 | C25: February | D25: 7493 | E25: =SUM(D22:D24)/3 -> 7414.3333 | G25: =D25-E25 -> 78.666667 | H25: =ABS(G25) -> 78.666667 | I25: =SUMSQ($G$6:G25)/(A25-3) -> 4663278.4 | J25: =SUM($H$6:H25)/(A25-3) -> 1658.5167 | K25: =H25/D25 -> 0.010498688 | L25: =SUM($K$6:K25)/(A25-3) -> 0.23799868 | M25: =SUM($G$6:G25) -> 4976.3333 | N25: =M25/J25 -> 3.0004723
A26: 24 | C26: March | D26: 8541 | E26: =SUM(D23:D25)/3 -> 7006.6667 | G26: =D26-E26 -> 1534.3333 | H26: =ABS(G26) -> 1534.3333 | I26: =SUMSQ($G$6:G26)/(A26-3) -> 4553321.3 | J26: =SUM($H$6:H26)/(A26-3) -> 1652.6032 | K26: =H26/D26 -> 0.17964329 | L26: =SUM($K$6:K26)/(A26-3) -> 0.23521985 | M26: =SUM($G$6:G26) -> 6510.6667 | N26: =M26/J26 -> 3.9396431
A27: 25 | C27: April | D27: 8029 | E27: =SUM(D24:D26)/3 -> 7814 | G27: =D27-E27 -> 215 | H27: =ABS(G27) -> 215 | I27: =SUMSQ($G$6:G27)/(A27-3) -> 4348453.3 | J27: =SUM($H$6:H27)/(A27-3) -> 1587.2576 | K27: =H27/D27 -> 0.02677793 | L27: =SUM($K$6:K27)/(A27-3) -> 0.22574522 | M27: =SUM($G$6:G27) -> 6725.6667 | N27: =M27/J27 -> 4.2372875
A28: 26 | C28: May | D28: 8650 | E28: =SUM(D25:D27)/3 -> 8021 | G28: =D28-E28 -> 629 | H28: =ABS(G28) -> 629 | I28: =SUMSQ($G$6:G28)/(A28-3) -> 4176591.9 | J28: =SUM($H$6:H28)/(A28-3) -> 1545.5942 | K28: =H28/D28 -> 0.072716763 | L28: =SUM($K$6:K28)/(A28-3) -> 0.21909181 | M28: =SUM($G$6:G28) -> 7354.6667 | N28: =M28/J28 -> 4.758472
A29: 27 | C29: June | D29: 9960 | E29: =SUM(D26:D28)/3 -> 8406.6667 | G29: =D29-E29 -> 1553.3333 | H29: =ABS(G29) -> 1553.3333 | I29: =SUMSQ($G$6:G29)/(A29-3) -> 4103102.4 | J29: =SUM($H$6:H29)/(A29-3) -> 1545.9167 | K29: =H29/D29 -> 0.15595716 | L29: =SUM($K$6:K29)/(A29-3) -> 0.2164612 | M29: =SUM($G$6:G29) -> 8908 | N29: =M29/J29 -> 5.762277
A30: 28 | C30: July | D30: 7152 | E30: =SUM(D27:D29)/3 -> 8879.6667 | G30: =D30-E30 -> -1727.6667 | H30: =ABS(G30) -> 1727.6667 | I30: =SUMSQ($G$6:G30)/(A30-3) -> 4058371.6 | J30: =SUM($H$6:H30)/(A30-3) -> 1553.1867 | K30: =H30/D30 -> 0.24156413 | L30: =SUM($K$6:K30)/(A30-3) -> 0.21746531 | M30: =SUM($G$6:G30) -> 7180.3333 | N30: =M30/J30 -> 4.6229687
A31: 29 | C31: August | D31: 7322 | E31: =SUM(D28:D30)/3 -> 8587.3333 | G31: =D31-E31 -> -1265.3333 | H31: =ABS(G31) -> 1265.3333 | I31: =SUMSQ($G$6:G31)/(A31-3) -> 3963859.9 | J31: =SUM($H$6:H31)/(A31-3) -> 1542.1154 | K31: =H31/D31 -> 0.17281253 | L31: =SUM($K$6:K31)/(A31-3) -> 0.2157479 | M31: =SUM($G$6:G31) -> 5915 | N31: =M31/J31 -> 3.8356404
A32: 30 | C32: September | D32: 9239 | E32: =SUM(D29:D31)/3 -> 8144.6667 | G32: =D32-E32 -> 1094.3333 | H32: =ABS(G32) -> 1094.3333 | I32: =SUMSQ($G$6:G32)/(A32-3) -> 3861404.6 | J32: =SUM($H$6:H32)/(A32-3) -> 1525.5309 | K32: =H32/D32 -> 0.11844716 | L32: =SUM($K$6:K32)/(A32-3) -> 0.21214417 | M32: =SUM($G$6:G32) -> 7009.3333 | N32: =M32/J32 -> 4.5946847
A33: 31 | C33: October | D33: 14123 | E33: =SUM(D30:D32)/3 -> 7904.3333 | G33: =D33-E33 -> 6218.6667 | H33: =ABS(G33) -> 6218.6667 | I33: =SUMSQ($G$6:G33)/(A33-3) -> 5104633.5 | J33: =SUM($H$6:H33)/(A33-3) -> 1693.1429 | K33: =H33/D33 -> 0.44032193 | L33: =SUM($K$6:K33)/(A33-3) -> 0.22029337 | M33: =SUM($G$6:G33) -> 13228 | N33: =M33/J33 -> 7.8126898
A34: 32 | C34: November | D34: 9566 | E34: =SUM(D31:D33)/3 -> 10228 | G34: =D34-E34 -> -662 | H34: =ABS(G34) -> 662 | I34: =SUMSQ($G$6:G34)/(A34-3) -> 4943723.5 | J34: =SUM($H$6:H34)/(A34-3) -> 1657.5862 | K34: =H34/D34 -> 0.069203429 | L34: =SUM($K$6:K34)/(A34-3) -> 0.21508338 | M34: =SUM($G$6:G34) -> 12566 | N34: =M34/J34 -> 7.5809029
A35: 33 | C35: December | D35: 7341 | E35: =SUM(D32:D34)/3 -> 10976 | G35: =D35-E35 -> -3635 | H35: =ABS(G35) -> 3635 | I35: =SUMSQ($G$6:G35)/(A35-3) -> 5219373.6 | J35: =SUM($H$6:H35)/(A35-3) -> 1723.5 | K35: =H35/D35 -> 0.49516415 | L35: =SUM($K$6:K35)/(A35-3) -> 0.2244194 | M35: =SUM($G$6:G35) -> 8931 | N35: =M35/J35 -> 5.1818973
A36: 34 | B36: 2006 | C36: January | D36: 9404 | E36: =SUM(D33:D35)/3 -> 10343.333 | G36: =D36-E36 -> -939.33333 | H36: =ABS(G36) -> 939.33333 | I36: =SUMSQ($G$6:G36)/(A36-3) -> 5079469.5 | J36: =SUM($H$6:H36)/(A36-3) -> 1698.2043 | K36: =H36/D36 -> 0.099886573 | L36: =SUM($K$6:K36)/(A36-3) -> 0.22040221 | M36: =SUM($G$6:G36) -> 7991.6667 | N36: =M36/J36 -> 4.7059513
A37: 35 | C37: February | D37: 8613 | E37: =SUM(D34:D36)/3 -> 8770.3333 | G37: =D37-E37 -> -157.33333 | H37: =ABS(G37) -> 157.33333 | I37: =SUMSQ($G$6:G37)/(A37-3) -> 4921509.6 | J37: =SUM($H$6:H37)/(A37-3) -> 1650.0521 | K37: =H37/D37 -> 0.018266961 | L37: =SUM($K$6:K37)/(A37-3) -> 0.21408549 | M37: =SUM($G$6:G37) -> 7834.3333 | N37: =M37/J37 -> 4.7479309
A38: 36 | C38: March | D38: 9425 | E38: =SUM(D35:D37)/3 -> 8452.6667 | G38: =D38-E38 -> 972.33333 | H38: =ABS(G38) -> 972.33333 | I38: =SUMSQ($G$6:G38)/(A38-3) -> 4801022.4 | J38: =SUM($H$6:H38)/(A38-3) -> 1629.5152 | K38: =H38/D38 -> 0.10316534 | L38: =SUM($K$6:K38)/(A38-3) -> 0.21072427 | M38: =SUM($G$6:G38) -> 8806.6667 | N38: =M38/J38 -> 5.4044706
A39: 37 | C39: April | D39: 10905 | E39: =SUM(D36:D38)/3 -> 9147.3333 | G39: =D39-E39 -> 1757.6667 | H39: =ABS(G39) -> 1757.6667 | I39: =SUMSQ($G$6:G39)/(A39-3) -> 4750680.4 | J39: =SUM($H$6:H39)/(A39-3) -> 1633.2843 | K39: =H39/D39 -> 0.16117989 | L39: =SUM($K$6:K39)/(A39-3) -> 0.20926708 | M39: =SUM($G$6:G39) -> 10564.333 | N39: =M39/J39 -> 6.4681533
A40: 38 | C40: May | D40: 9842 | E40: =SUM(D37:D39)/3 -> 9647.6667 | G40: =D40-E40 -> 194.33333 | H40: =ABS(G40) -> 194.33333 | I40: =SUMSQ($G$6:G40)/(A40-3) -> 4616025.7 | J40: =SUM($H$6:H40)/(A40-3) -> 1592.1714 | K40: =H40/D40 -> 0.019745309 | L40: =SUM($K$6:K40)/(A40-3) -> 0.20385218 | M40: =SUM($G$6:G40) -> 10758.667 | N40: =M40/J40 -> 6.7572288
A41: 39 | C41: June | D41: 12259 | E41: =SUM(D38:D40)/3 -> 10057.333 | G41: =D41-E41 -> 2201.6667 | H41: =ABS(G41) -> 2201.6667 | I41: =SUMSQ($G$6:G41)/(A41-3) -> 4622450.9 | J41: =SUM($H$6:H41)/(A41-3) -> 1609.1019 | K41: =H41/D41 -> 0.17959594 | L41: =SUM($K$6:K41)/(A41-3) -> 0.20317839 | M41: =SUM($G$6:G41) -> 12960.333 | N41: =M41/J41 -> 8.0543897
...

Sheet MA (4m)
A2: #Month | B2: Year | C2: Month | D2: Actual Demand | E2: 4 Month Moving Average | G2: Forecast error | H2: Absolute value | I2: MSE | J2: MAD | K2: %FE | L2: MAPE | M2: Bias | N2: TS
A3: 1 | B3: 2003 | C3: April | D3: 4698
A4: 2 | C4: May | D4: 4605
A5: 3 | C5: June | D5: 4859
A6: 4 | C6: July | D6: 4136
A7: 5 | C7: August | D7: 3872 | E7: =SUM(D3:D6)/4 -> 4574.5 | G7: =D7-E7 -> -702.5 | H7: =ABS(G7) -> 702.5 | I7: =SUMSQ($G$7:G7)/(A7-4) -> 493506.25 | J7: =SUM($H$7:H7)/(A7-4) -> 702.5 | K7: =H7/D7 -> 0.18143079 | L7: =SUM($K$7:K7)/(A7-4) -> 0.18143079 | M7: =SUM($G$7:G7) -> -702.5 | N7: =M7/J7 -> -1
A8: 6 | C8: September | D8: 5938 | E8: =SUM(D4:D7)/4 -> 4368 | G8: =D8-E8 -> 1570 | H8: =ABS(G8) -> 1570 | I8: =SUMSQ($G$7:G8)/(A8-4) -> 1479203.1 | J8: =SUM($H$7:H8)/(A8-4) -> 1136.25 | K8: =H8/D8 -> 0.26439879 | L8: =SUM($K$7:K8)/(A8-4) -> 0.22291479 | M8: =SUM($G$7:G8) -> 867.5 | N8: =M8/J8 -> 0.76347635
A9: 7 | C9: October | D9: 8790 | E9: =SUM(D5:D8)/4 -> 4701.25 | G9: =D9-E9 -> 4088.75 | H9: =ABS(G9) -> 4088.75 | I9: =SUMSQ($G$7:G9)/(A9-4) -> 6558760.9 | J9: =SUM($H$7:H9)/(A9-4) -> 2120.4167 | K9: =H9/D9 -> 0.46515927 | L9: =SUM($K$7:K9)/(A9-4) -> 0.30366295 | M9: =SUM($G$7:G9) -> 4956.25 | N9: =M9/J9 -> 2.3373944
A10: 8 | C10: November | D10: 6825 | E10: =SUM(D6:D9)/4 -> 5684 | G10: =D10-E10 -> 1141 | H10: =ABS(G10) -> 1141 | I10: =SUMSQ($G$7:G10)/(A10-4) -> 5244541 | J10: =SUM($H$7:H10)/(A10-4) -> 1875.5625 | K10: =H10/D10 -> 0.16717949 | L10: =SUM($K$7:K10)/(A10-4) -> 0.26954208 | M10: =SUM($G$7:G10) -> 6097.25 | N10: =M10/J10 -> 3.2508914
A11: 9 | C11: December | D11: 4858 | E11: =SUM(D7:D10)/4 -> 6356.25 | G11: =D11-E11 -> -1498.25 | H11: =ABS(G11) -> 1498.25 | I11: =SUMSQ($G$7:G11)/(A11-4) -> 4644583.4 | J11: =SUM($H$7:H11)/(A11-4) -> 1800.1 | K11: =H11/D11 -> 0.30840881 | L11: =SUM($K$7:K11)/(A11-4) -> 0.27731543 | M11: =SUM($G$7:G11) -> 4599 | N11: =M11/J11 -> 2.5548581
A12: 10 | B12: 2004 | C12: January | D12: 5907 | E12: =SUM(D8:D11)/4 -> 6602.75 | G12: =D12-E12 -> -695.75 | H12: =ABS(G12) -> 695.75 | I12: =SUMSQ($G$7:G12)/(A12-4) -> 3951164.2 | J12: =SUM($H$7:H12)/(A12-4) -> 1616.0417 | K12: =H12/D12 -> 0.11778399 | L12: =SUM($K$7:K12)/(A12-4) -> 0.25072685 | M12: =SUM($G$7:G12) -> 3903.25 | N12: =M12/J12 -> 2.4153152
A13: 11 | C13: February | D13: 6386 | E13: =SUM(D9:D12)/4 -> 6595 | G13: =D13-E13 -> -209 | H13: =ABS(G13) -> 209 | I13: =SUMSQ($G$7:G13)/(A13-4) -> 3392952.3 | J13: =SUM($H$7:H13)/(A13-4) -> 1415.0357 | K13: =H13/D13 -> 0.032727842 | L13: =SUM($K$7:K13)/(A13-4) -> 0.21958414 | M13: =SUM($G$7:G13) -> 3694.25 | N13: =M13/J13 -> 2.6107115
A14: 12 | C14: March | D14: 9085 | E14: =SUM(D10:D13)/4 -> 5994 | G14: =D14-E14 -> 3091 | H14: =ABS(G14) -> 3091 | I14: =SUMSQ($G$7:G14)/(A14-4) -> 4163118.4 | J14: =SUM($H$7:H14)/(A14-4) -> 1624.5312 | K14: =H14/D14 -> 0.34023115 | L14: =SUM($K$7:K14)/(A14-4) -> 0.23466501 | M14: =SUM($G$7:G14) -> 6785.25 | N14: =M14/J14 -> 4.1767433
A15: 13 | C15: April | D15: 6492 | E15: =SUM(D11:D14)/4 -> 6559 | G15: =D15-E15 -> -67 | H15: =ABS(G15) -> 67 | I15: =SUMSQ($G$7:G15)/(A15-4) -> 3701048.4 | J15: =SUM($H$7:H15)/(A15-4) -> 1451.4722 | K15: =H15/D15 -> 0.010320394 | L15: =SUM($K$7:K15)/(A15-4) -> 0.20973783 | M15: =SUM($G$7:G15) -> 6718.25 | N15: =M15/J15 -> 4.6285763
A16: 14 | C16: May | D16: 6832 | E16: =SUM(D12:D15)/4 -> 6967.5 | G16: =D16-E16 -> -135.5 | H16: =ABS(G16) -> 135.5 | I16: =SUMSQ($G$7:G16)/(A16-4) -> 3332779.6 | J16: =SUM($H$7:H16)/(A16-4) -> 1319.875 | K16: =H16/D16 -> 0.019833138 | L16: =SUM($K$7:K16)/(A16-4) -> 0.19074737 | M16: =SUM($G$7:G16) -> 6582.75 | N16: =M16/J16 -> 4.9874041
A17: 15 | C17: June | D17: 8867 | E17: =SUM(D13:D16)/4 -> 7198.75 | G17: =D17-E17 -> 1668.25 | H17: =ABS(G17) -> 1668.25 | I17: =SUMSQ($G$7:G17)/(A17-4) -> 3282804.9 | J17: =SUM($H$7:H17)/(A17-4) -> 1351.5455 | K17: =H17/D17 -> 0.18814142 | L17: =SUM($K$7:K17)/(A17-4) -> 0.19051046 | M17: =SUM($G$7:G17) -> 8251 | N17: =M17/J17 -> 6.1048631
A18: 16 | C18: July | D18: 4998 | E18: =SUM(D14:D17)/4 -> 7819 | G18: =D18-E18 -> -2821 | H18: =ABS(G18) -> 2821 | I18: =SUMSQ($G$7:G18)/(A18-4) -> 3672407.9 | J18: =SUM($H$7:H18)/(A18-4) -> 1474 | K18: =H18/D18 -> 0.56442577 | L18: =SUM($K$7:K18)/(A18-4) -> 0.22167007 | M18: =SUM($G$7:G18) -> 5430 | N18: =M18/J18 -> 3.6838535
A19: 17 | C19: August | D19: 5305 | E19: =SUM(D15:D18)/4 -> 6797.25 | G19: =D19-E19 -> -1492.25 | H19: =ABS(G19) -> 1492.25 | I19: =SUMSQ($G$7:G19)/(A19-4) -> 3561208.1 | J19: =SUM($H$7:H19)/(A19-4) -> 1475.4038 | K19: =H19/D19 -> 0.28129123 | L19: =SUM($K$7:K19)/(A19-4) -> 0.22625631 | M19: =SUM($G$7:G19) -> 3937.75 | N19: =M19/J19 -> 2.6689303
A20: 18 | C20: September | D20: 7618 | E20: =SUM(D16:D19)/4 -> 6500.5 | G20: =D20-E20 -> 1117.5 | H20: =ABS(G20) -> 1117.5 | I20: =SUMSQ($G$7:G20)/(A20-4) -> 3396036.5 | J20: =SUM($H$7:H20)/(A20-4) -> 1449.8393 | K20: =H20/D20 -> 0.14669205 | L20: =SUM($K$7:K20)/(A20-4) -> 0.22057315 | M20: =SUM($G$7:G20) -> 5055.25 | N20: =M20/J20 -> 3.4867658
A21: 19 | C21: October | D21: 11443 | E21: =SUM(D17:D20)/4 -> 6697 | G21: =D21-E21 -> 4746 | H21: =ABS(G21) -> 4746 | I21: =SUMSQ($G$7:G21)/(A21-4) -> 4671268.5 | J21: =SUM($H$7:H21)/(A21-4) -> 1669.5833 | K21: =H21/D21 -> 0.41475138 | L21: =SUM($K$7:K21)/(A21-4) -> 0.23351837 | M21: =SUM($G$7:G21) -> 9801.25 | N21: =M21/J21 -> 5.8704767
A22: 20 | C22: November | D22: 8716 | E22: =SUM(D18:D21)/4 -> 7341 | G22: =D22-E22 -> 1375 | H22: =ABS(G22) -> 1375 | I22: =SUMSQ($G$7:G22)/(A22-4) -> 4497478.3 | J22: =SUM($H$7:H22)/(A22-4) -> 1651.1719 | K22: =H22/D22 -> 0.15775585 | L22: =SUM($K$7:K22)/(A22-4) -> 0.22878321 | M22: =SUM($G$7:G22) -> 11176.25 | N22: =M22/J22 -> 6.7686775
A23: 21 | C23: December | D23: 6119 | E23: =SUM(D19:D22)/4 -> 8270.5 | G23: =D23-E23 -> -2151.5 | H23: =ABS(G23) -> 2151.5 | I23: =SUMSQ($G$7:G23)/(A23-4) -> 4505212 | J23: =SUM($H$7:H23)/(A23-4) -> 1680.6029 | K23: =H23/D23 -> 0.35160974 | L23: =SUM($K$7:K23)/(A23-4) -> 0.2360083 | M23: =SUM($G$7:G23) -> 9024.75 | N23: =M23/J23 -> 5.3699478
A24: 22 | B24: 2005 | C24: January | D24: 7408 | E24: =SUM(D20:D23)/4 -> 8474 | G24: =D24-E24 -> -1066 | H24: =ABS(G24) -> 1066 | I24: =SUMSQ($G$7:G24)/(A24-4) -> 4318053.4 | J24: =SUM($H$7:H24)/(A24-4) -> 1646.4583 | K24: =H24/D24 -> 0.14389849 | L24: =SUM($K$7:K24)/(A24-4) -> 0.23089109 | M24: =SUM($G$7:G24) -> 7958.75 | N24: =M24/J24 -> 4.8338606
A25: 23 | C25: February | D25: 7493 | E25: =SUM(D21:D24)/4 -> 8421.5 | G25: =D25-E25 -> -928.5 | H25: =ABS(G25) -> 928.5 | I25: =SUMSQ($G$7:G25)/(A25-4) -> 4136161.7 | J25: =SUM($H$7:H25)/(A25-4) -> 1608.6711 | K25: =H25/D25 -> 0.12391565 | L25: =SUM($K$7:K25)/(A25-4) -> 0.2252608 | M25: =SUM($G$7:G25) -> 7030.25 | N25: =M25/J25 -> 4.3702222
A26: 24 | C26: March | D26: 8541 | E26: =SUM(D22:D25)/4 -> 7434 | G26: =D26-E26 -> 1107 | H26: =ABS(G26) -> 1107 | I26: =SUMSQ($G$7:G26)/(A26-4) -> 3990626.1 | J26: =SUM($H$7:H26)/(A26-4) -> 1583.5875 | K26: =H26/D26 -> 0.12961012 | L26: =SUM($K$7:K26)/(A26-4) -> 0.22047827 | M26: =SUM($G$7:G26) -> 8137.25 | N26: =M26/J26 -> 5.1384909
A27: 25 | C27: April | D27: 8029 | E27: =SUM(D23:D26)/4 -> 7390.25 | G27: =D27-E27 -> 638.75 | H27: =ABS(G27) -> 638.75 | I27: =SUMSQ($G$7:G27)/(A27-4) -> 3820024.9 | J27: =SUM($H$7:H27)/(A27-4) -> 1538.5952 | K27: =H27/D27 -> 0.079555362 | L27: =SUM($K$7:K27)/(A27-4) -> 0.21376765 | M27: =SUM($G$7:G27) -> 8776 | N27: =M27/J27 -> 5.7039043
A28: 26 | C28: May | D28: 8650 | E28: =SUM(D24:D27)/4 -> 7867.75 | G28: =D28-E28 -> 782.25 | H28: =ABS(G28) -> 782.25 | I28: =SUMSQ($G$7:G28)/(A28-4) -> 3674201.8 | J28: =SUM($H$7:H28)/(A28-4) -> 1504.2159 | K28: =H28/D28 -> 0.090433526 | L28: =SUM($K$7:K28)/(A28-4) -> 0.20816156 | M28: =SUM($G$7:G28) -> 9558.25 | N28: =M28/J28 -> 6.3543072
A29: 27 | C29: June | D29: 9960 | E29: =SUM(D25:D28)/4 -> 8178.25 | G29: =D29-E29 -> 1781.75 | H29: =ABS(G29) -> 1781.75 | I29: =SUMSQ($G$7:G29)/(A29-4) -> 3652481.4 | J29: =SUM($H$7:H29)/(A29-4) -> 1516.2826 | K29: =H29/D29 -> 0.17889056 | L29: =SUM($K$7:K29)/(A29-4) -> 0.2068889 | M29: =SUM($G$7:G29) -> 11340 | N29: =M29/J29 -> 7.4788169
A30: 28 | C30: July | D30: 7152 | E30: =SUM(D26:D29)/4 -> 8795 | G30: =D30-E30 -> -1643 | H30: =ABS(G30) -> 1643 | I30: =SUMSQ($G$7:G30)/(A30-4) -> 3612771.7 | J30: =SUM($H$7:H30)/(A30-4) -> 1521.5625 | K30: =H30/D30 -> 0.22972595 | L30: =SUM($K$7:K30)/(A30-4) -> 0.20784045 | M30: =SUM($G$7:G30) -> 9697 | N30: =M30/J30 -> 6.373054
A31: 29 | C31: August | D31: 7322 | E31: =SUM(D27:D30)/4 -> 8447.75 | G31: =D31-E31 -> -1125.75 | H31: =ABS(G31) -> 1125.75 | I31: =SUMSQ($G$7:G31)/(A31-4) -> 3518953.4 | J31: =SUM($H$7:H31)/(A31-4) -> 1505.73 | K31: =H31/D31 -> 0.15374898 | L31: =SUM($K$7:K31)/(A31-4) -> 0.20567679 | M31: =SUM($G$7:G31) -> 8571.25 | N31: =M31/J31 -> 5.6924216
A32: 30 | C32: September | D32: 9239 | E32: =SUM(D28:D31)/4 -> 8271 | G32: =D32-E32 -> 968 | H32: =ABS(G32) -> 968 | I32: =SUMSQ($G$7:G32)/(A32-4) -> 3419648.4 | J32: =SUM($H$7:H32)/(A32-4) -> 1485.0481 | K32: =H32/D32 -> 0.10477324 | L32: =SUM($K$7:K32)/(A32-4) -> 0.20179588 | M32: =SUM($G$7:G32) -> 9539.25 | N32: =M32/J32 -> 6.4235294
A33: 31 | C33: October | D33: 14123 | E33: =SUM(D29:D32)/4 -> 8418.25 | G33: =D33-E33 -> 5704.75 | H33: =ABS(G33) -> 5704.75 | I33: =SUMSQ($G$7:G33)/(A33-4) -> 4498334.5 | J33: =SUM($H$7:H33)/(A33-4) -> 1641.3333 | K33: =H33/D33 -> 0.4039333 | L33: =SUM($K$7:K33)/(A33-4) -> 0.20928245 | M33: =SUM($G$7:G33) -> 15244 | N33: =M33/J33 -> 9.2875711
A34: 32 | C34: November | D34: 9566 | E34: =SUM(D30:D33)/4 -> 9459 | G34: =D34-E34 -> 107 | H34: =ABS(G34) -> 107 | I34: =SUMSQ($G$7:G34)/(A34-4) -> 4338088.5 | J34: =SUM($H$7:H34)/(A34-4) -> 1586.5357 | K34: =H34/D34 -> 0.011185448 | L34: =SUM($K$7:K34)/(A34-4) -> 0.20220756 | M34: =SUM($G$7:G34) -> 15351 | N34: =M34/J34 -> 9.6757986
A35: 33 | C35: December | D35: 7341 | E35: =SUM(D31:D34)/4 -> 10062.5 | G35: =D35-E35 -> -2721.5 | H35: =ABS(G35) -> 2721.5 | I35: =SUMSQ($G$7:G35)/(A35-4) -> 4443898 | J35: =SUM($H$7:H35)/(A35-4) -> 1625.6724 | K35: =H35/D35 -> 0.37072606 | L35: =SUM($K$7:K35)/(A35-4) -> 0.20801854 | M35: =SUM($G$7:G35) -> 12629.5 | N35: =M35/J35 -> 7.7687853
A36: 34 | B36: 2006 | C36: January | D36: 9404 | E36: =SUM(D32:D35)/4 -> 10067.25 | G36: =D36-E36 -> -663.25 | H36: =ABS(G36) -> 663.25 | I36: =SUMSQ($G$7:G36)/(A36-4) -> 4310431.4 | J36: =SUM($H$7:H36)/(A36-4) -> 1593.5917 | K36: =H36/D36 -> 0.070528499 | L36: =SUM($K$7:K36)/(A36-4) -> 0.20343554 | M36: =SUM($G$7:G36) -> 11966.25 | N36: =M36/J36 -> 7.5089813
A37: 35 | C37: February | D37: 8613 | E37: =SUM(D33:D36)/4 -> 10108.5 | G37: =D37-E37 -> -1495.5 | H37: =ABS(G37) -> 1495.5 | I37: =SUMSQ($G$7:G37)/(A37-4) -> 4243531 | J37: =SUM($H$7:H37)/(A37-4) -> 1590.4274 | K37: =H37/D37 -> 0.17363288 | L37: =SUM($K$7:K37)/(A37-4) -> 0.20247417 | M37: =SUM($G$7:G37) -> 10470.75 | N37: =M37/J37 -> 6.5836076
A38: 36 | C38: March | D38: 9425 | E38: =SUM(D34:D37)/4 -> 8731 | G38: =D38-E38 -> 694 | H38: =ABS(G38) -> 694 | I38: =SUMSQ($G$7:G38)/(A38-4) -> 4125971.8 | J38: =SUM($H$7:H38)/(A38-4) -> 1562.4141 | K38: =H38/D38 -> 0.073633952 | L38: =SUM($K$7:K38)/(A38-4) -> 0.19844791 | M38: =SUM($G$7:G38) -> 11164.75 | N38: =M38/J38 -> 7.145833
A39: 37 | C39: April | D39: 10905 | E39: =SUM(D35:D38)/4 -> 8695.75 | G39: =D39-E39 -> 2209.25 | H39: =ABS(G39) -> 2209.25 | I39: =SUMSQ($G$7:G39)/(A39-4) -> 4148845 | J39: =SUM($H$7:H39)/(A39-4) -> 1582.0152 | K39: =H39/D39 -> 0.20259055 | L39: =SUM($K$7:K39)/(A39-4) -> 0.19857344 | M39: =SUM($G$7:G39) -> 13374 | N39: =M39/J39 -> 8.4537749
A40: 38 | C40: May | D40: 9842 | E40: =SUM(D36:D39)/4 -> 9586.75 | G40: =D40-E40 -> 255.25 | H40: =ABS(G40) -> 255.25 | I40: =SUMSQ($G$7:G40)/(A40-4) -> 4028736.4 | J40: =SUM($H$7:H40)/(A40-4) -> 1542.9926 | K40: =H40/D40 -> 0.025934769 | L40: =SUM($K$7:K40)/(A40-4) -> 0.19349584 | M40: =SUM($G$7:G40) -> 13629.25 | N40: =M40/J40 -> 8.8329974
A41: 39 | C41: June | D41: 12259 | E41: =SUM(D37:D40)/4 -> 9696.25 | G41: =D41-E41 -> 2562.75 | H41: =ABS(G41) -> 2562.75 | I41: =SUMSQ($G$7:G41)/(A41-4) -> 4101277.8 | J41: =SUM($H$7:H41)/(A41-4) -> 1572.1286 | K41: =H41/D41 -> 0.20905049 | L41: =SUM($K$7:K41)/(A41-4) -> 0.19394026 | M41: =SUM($G$7:G41) -> 16192 | N41: =M41/J41 -> 10.299412
...

Sheet WMA (3m)
D1: Weights are | E1: 0.54810273 | F1: 0 | G1: 0.45189727 | I1: =E1+F1+G1 -> 1
E2: Last month | F2: 2mon ago | G2: 3mon ago
A4: #Month | B4: Year | C4: Month | D4: Actual Demand | E4: 3 Month Weighted MovAver | G4: Forecast error | H4: Absolute value | I4: MSE | J4: MAD | K4: APE | L4: MAPE | M4: Bias | N4: TS
A5: 1 | B5: 2003 | C5: April | D5: 4698
A6: 2 | C6: May | D6: 4605
A7: 3 | C7: June | D7: 4859
A8: 4 | C8: July | D8: 4136 | E8: =(D7*$E$1+D6*$F$1+D5*$G$1)/SUM($E$1:$G$1) -> 4786.2445 | G8: =D8-E8 -> -650.24454 | H8: =ABS(G8) -> 650.24454 | I8: =SUMSQ($G$8:G8)/(A8-3) -> 422817.96 | J8: =SUM($H$8:H8)/(A8-3) -> 650.24454 | K8: =H8/D8 -> 0.1572158 | L8: =SUM($K$8:K8)/(A8-3) -> 0.1572158 | M8: =SUM($G$8:G8) -> -650.24454 | N8: =M8/J8 -> -1
A9: 5 | C9: August | D9: 3872 | E9: =(D8*$E$1+D7*$F$1+D6*$G$1)/SUM($E$1:$G$1) -> 4347.9398 | G9: =D9-E9 -> -475.93982 | H9: =ABS(G9) -> 475.93982 | I9: =SUMSQ($G$8:G9)/(A9-3) -> 324668.34 | J9: =SUM($H$8:H9)/(A9-3) -> 563.09218 | K9: =H9/D9 -> 0.12291834 | L9: =SUM($K$8:K9)/(A9-3) -> 0.14006707 | M9: =SUM($G$8:G9) -> -1126.1844 | N9: =M9/J9 -> -2
A10: 6 | C10: September | D10: 5938 | E10: =(D9*$E$1+D8*$F$1+D7*$G$1)/SUM($E$1:$G$1) -> 4318.0226 | G10: =D10-E10 -> 1619.9774 | H10: =ABS(G10) -> 1619.9774 | I10: =SUMSQ($G$8:G10)/(A10-3) -> 1091221.1 | J10: =SUM($H$8:H10)/(A10-3) -> 915.38725 | K10: =H10/D10 -> 0.27281532 | L10: =SUM($K$8:K10)/(A10-3) -> 0.18431649 | M10: =SUM($G$8:G10) -> 493.79303 | N10: =M10/J10 -> 0.53943621
A11: 7 | C11: October | D11: 8790 | E11: =(D10*$E$1+D9*$F$1+D8*$G$1)/SUM($E$1:$G$1) -> 5123.6811 | G11: =D11-E11 -> 3666.3189 | H11: =ABS(G11) -> 3666.3189 | I11: =SUMSQ($G$8:G11)/(A11-3) -> 4178889.4 | J11: =SUM($H$8:H11)/(A11-3) -> 1603.1202 | K11: =H11/D11 -> 0.41710112 | L11: =SUM($K$8:K11)/(A11-3) -> 0.24251265 | M11: =SUM($G$8:G11) -> 4160.1119 | N11: =M11/J11 -> 2.5950094
A12: 8 | C12: November | D12: 6825 | E12: =(D11*$E$1+D10*$F$1+D9*$G$1)/SUM($E$1:$G$1) -> 6567.5692 | G12: =D12-E12 -> 257.43079 | H12: =ABS(G12) -> 257.43079 | I12: =SUMSQ($G$8:G12)/(A12-3) -> 3356365.6 | J12: =SUM($H$8:H12)/(A12-3) -> 1333.9823 | K12: =H12/D12 -> 0.037718797 | L12: =SUM($K$8:K12)/(A12-3) -> 0.20155388 | M12: =SUM($G$8:G12) -> 4417.5427 | N12: =M12/J12 -> 3.3115453
A13: 9 | C13: December | D13: 4858 | E13: =(D12*$E$1+D11*$F$1+D10*$G$1)/SUM($E$1:$G$1) -> 6424.1671 | G13: =D13-E13 -> -1566.1671 | H13: =ABS(G13) -> 1566.1671 | I13: =SUMSQ($G$8:G13)/(A13-3) -> 3205784.6 | J13: =SUM($H$8:H13)/(A13-3) -> 1372.6798 | K13: =H13/D13 -> 0.32238928 | L13: =SUM($K$8:K13)/(A13-3) -> 0.22169311 | M13: =SUM($G$8:G13) -> 2851.3756 | N13: =M13/J13 -> 2.0772329
A14: 10 | B14: 2004 | C14: January | D14: 5907 | E14: =(D13*$E$1+D12*$F$1+D11*$G$1)/SUM($E$1:$G$1) -> 6634.8601 | G14: =D14-E14 -> -727.86008 | H14: =ABS(G14) -> 727.86008 | I14: =SUMSQ($G$8:G14)/(A14-3) -> 2823498.3 | J14: =SUM($H$8:H14)/(A14-3) -> 1280.5627 | K14: =H14/D14 -> 0.12321992 | L14: =SUM($K$8:K14)/(A14-3) -> 0.20762551 | M14: =SUM($G$8:G14) -> 2123.5155 | N14: =M14/J14 -> 1.6582676
A15: 11 | C15: February | D15: 6386 | E15: =(D14*$E$1+D13*$F$1+D12*$G$1)/SUM($E$1:$G$1) -> 6321.8417 | G15: =D15-E15 -> 64.158303 | H15: =ABS(G15) -> 64.158303 | I15: =SUMSQ($G$8:G15)/(A15-3) -> 2471075.5 | J15: =SUM($H$8:H15)/(A15-3) -> 1128.5121 | K15: =H15/D15 -> 0.010046712 | L15: =SUM($K$8:K15)/(A15-3) -> 0.18292816 | M15: =SUM($G$8:G15) -> 2187.6738 | N15: =M15/J15 -> 1.938547
A16: 12 | C16: March | D16: 9085 | E16: =(D15*$E$1+D14*$F$1+D13*$G$1)/SUM($E$1:$G$1) -> 5695.501 | G16: =D16-E16 -> 3389.499 | H16: =ABS(G16) -> 3389.499 | I16: =SUMSQ($G$8:G16)/(A16-3) -> 3473034.2 | J16: =SUM($H$8:H16)/(A16-3) -> 1379.7329 | K16: =H16/D16 -> 0.3730874 | L16: =SUM($K$8:K16)/(A16-3) -> 0.20405697 | M16: =SUM($G$8:G16) -> 5577.1728 | N16: =M16/J16 -> 4.042212
A17: 13 | C17: April | D17: 6492 | E17: =(D16*$E$1+D15*$F$1+D14*$G$1)/SUM($E$1:$G$1) -> 7648.8705 | G17: =D17-E17 -> -1156.8705 | H17: =ABS(G17) -> 1156.8705 | I17: =SUMSQ($G$8:G17)/(A17-3) -> 3259565.7 | J17: =SUM($H$8:H17)/(A17-3) -> 1357.4466 | K17: =H17/D17 -> 0.17819939 | L17: =SUM($K$8:K17)/(A17-3) -> 0.20147121 | M17: =SUM($G$8:G17) -> 4420.3024 | N17: =M17/J17 -> 3.256336
A18: 14 | C18: May | D18: 6832 | E18: =(D17*$E$1+D16*$F$1+D15*$G$1)/SUM($E$1:$G$1) -> 6444.0989 | G18: =D18-E18 -> 387.90111 | H18: =ABS(G18) -> 387.90111 | I18: =SUMSQ($G$8:G18)/(A18-3) -> 2976920.4 | J18: =SUM($H$8:H18)/(A18-3) -> 1269.3061 | K18: =H18/D18 -> 0.056777095 | L18: =SUM($K$8:K18)/(A18-3) -> 0.1883172 | M18: =SUM($G$8:G18) -> 4808.2035 | N18: =M18/J18 -> 3.7880566
A19: 15 | C19: June | D19: 8867 | E19: =(D18*$E$1+D17*$F$1+D16*$G$1)/SUM($E$1:$G$1) -> 7850.1246 | G19: =D19-E19 -> 1016.8754 | H19: =ABS(G19) -> 1016.8754 | I19: =SUMSQ($G$8:G19)/(A19-3) -> 2815013.3 | J19: =SUM($H$8:H19)/(A19-3) -> 1248.2702 | K19: =H19/D19 -> 0.11468089 | L19: =SUM($K$8:K19)/(A19-3) -> 0.18218084 | M19: =SUM($G$8:G19) -> 5825.0789 | N19: =M19/J19 -> 4.6665207
A20: 16 | C20: July | D20: 4998 | E20: =(D19*$E$1+D18*$F$1+D17*$G$1)/SUM($E$1:$G$1) -> 7793.744 | G20: =D20-E20 -> -2795.744 | H20: =ABS(G20) -> 2795.744 | I20: =SUMSQ($G$8:G20)/(A20-3) -> 3199718.8 | J20: =SUM($H$8:H20)/(A20-3) -> 1367.3067 | K20: =H20/D20 -> 0.55937254 | L20: =SUM($K$8:K20)/(A20-3) -> 0.21119559 | M20: =SUM($G$8:G20) -> 3029.335 | N20: =M20/J20 -> 2.215549
A21: 17 | C21: August | D21: 5305 | E21: =(D20*$E$1+D19*$F$1+D18*$G$1)/SUM($E$1:$G$1) -> 5826.7796 | G21: =D21-E21 -> -521.7796 | H21: =ABS(G21) -> 521.7796 | I21: =SUMSQ($G$8:G21)/(A21-3) -> 2990614.2 | J21: =SUM($H$8:H21)/(A21-3) -> 1306.9119 | K21: =H21/D21 -> 0.098356192 | L21: =SUM($K$8:K21)/(A21-3) -> 0.20313563 | M21: =SUM($G$8:G21) -> 2507.5554 | N21: =M21/J21 -> 1.9186874
A22: 18 | C22: September | D22: 7618 | E22: =(D21*$E$1+D20*$F$1+D19*$G$1)/SUM($E$1:$G$1) -> 6914.6581 | G22: =D22-E22 -> 703.34191 | H22: =ABS(G22) -> 703.34191 | I22: =SUMSQ($G$8:G22)/(A22-3) -> 2824219.2 | J22: =SUM($H$8:H22)/(A22-3) -> 1266.6739 | K22: =H22/D22 -> 0.092326321 | L22: =SUM($K$8:K22)/(A22-3) -> 0.19574834 | M22: =SUM($G$8:G22) -> 3210.8973 | N22: =M22/J22 -> 2.5349044
A23: 19 | C23: October | D23: 11443 | E23: =(D22*$E$1+D21*$F$1+D20*$G$1)/SUM($E$1:$G$1) -> 6434.0291 | G23: =D23-E23 -> 5008.9709 | H23: =ABS(G23) -> 5008.9709 | I23: =SUMSQ($G$8:G23)/(A23-3) -> 4215817.3 | J23: =SUM($H$8:H23)/(A23-3) -> 1500.5675 | K23: =H23/D23 -> 0.43773231 | L23: =SUM($K$8:K23)/(A23-3) -> 0.21087234 | M23: =SUM($G$8:G23) -> 8219.8681 | N23: =M23/J23 -> 5.4778398
A24: 20 | C24: November | D24: 8716 | E24: =(D23*$E$1+D22*$F$1+D21*$G$1)/SUM($E$1:$G$1) -> 8669.2545 | G24: =D24-E24 -> 46.745464 | H24: =ABS(G24) -> 46.745464 | I24: =SUMSQ($G$8:G24)/(A24-3) -> 3967956.6 | J24: =SUM($H$8:H24)/(A24-3) -> 1415.0485 | K24: =H24/D24 -> 0.0053631785 | L24: =SUM($K$8:K24)/(A24-3) -> 0.19878357 | M24: =SUM($G$8:G24) -> 8266.6136 | N24: =M24/J24 -> 5.8419294
A25: 21 | C25: December | D25: 6119 | E25: =(D24*$E$1+D23*$F$1+D22*$G$1)/SUM($E$1:$G$1) -> 8219.8168 | G25: =D25-E25 -> -2100.8168 | H25: =ABS(G25) -> 2100.8168 | I25: =SUMSQ($G$8:G25)/(A25-3) -> 3992705.2 | J25: =SUM($H$8:H25)/(A25-3) -> 1453.1468 | K25: =H25/D25 -> 0.34332682 | L25: =SUM($K$8:K25)/(A25-3) -> 0.20681375 | M25: =SUM($G$8:G25) -> 6165.7968 | N25: =M25/J25 -> 4.2430655
A26: 22 | B26: 2005 | C26: January | D26: 7408 | E26: =(D25*$E$1+D24*$F$1+D23*$G$1)/SUM($E$1:$G$1) -> 8524.9011 | G26: =D26-E26 -> -1116.9011 | H26: =ABS(G26) -> 1116.9011 | I26: =SUMSQ($G$8:G26)/(A26-3) -> 3848219 | J26: =SUM($H$8:H26)/(A26-3) -> 1435.4496 | K26: =H26/D26 -> 0.15076958 | L26: =SUM($K$8:K26)/(A26-3) -> 0.20386405 | M26: =SUM($G$8:G26) -> 5048.8957 | N26: =M26/J26 -> 3.5172922
A27: 23 | C27: February | D27: 7493 | E27: =(D26*$E$1+D25*$F$1+D24*$G$1)/SUM($E$1:$G$1) -> 7999.0816 | G27: =D27-E27 -> -506.08163 | H27: =ABS(G27) -> 506.08163 | I27: =SUMSQ($G$8:G27)/(A27-3) -> 3668614 | J27: =SUM($H$8:H27)/(A27-3) -> 1388.9812 | K27: =H27/D27 -> 0.067540589 | L27: =SUM($K$8:K27)/(A27-3) -> 0.19704788 | M27: =SUM($G$8:G27) -> 4542.8141 | N27: =M27/J27 -> 3.2706087
A28: 24 | C28: March | D28: 8541 | E28: =(D27*$E$1+D26*$F$1+D25*$G$1)/SUM($E$1:$G$1) -> 6872.0931 | G28: =D28-E28 -> 1668.9069 | H28: =ABS(G28) -> 1668.9069 | I28: =SUMSQ($G$8:G28)/(A28-3) -> 3626549.1 | J28: =SUM($H$8:H28)/(A28-3) -> 1402.311 | K28: =H28/D28 -> 0.19539947 | L28: =SUM($K$8:K28)/(A28-3) -> 0.19696938 | M28: =SUM($G$8:G28) -> 6211.7209 | N28: =M28/J28 -> 4.4296314
A29: 25 | C29: April | D29: 8029 | E29: =(D28*$E$1+D27*$F$1+D26*$G$1)/SUM($E$1:$G$1) -> 8029.0004 | G29: =D29-E29 -> -0.00038927246 | H29: =ABS(G29) -> 0.00038927246 | I29: =SUMSQ($G$8:G29)/(A29-3) -> 3461705.9 | J29: =SUM($H$8:H29)/(A29-3) -> 1338.5696 | K29: =H29/D29 -> 4.8483305e-08 | L29: =SUM($K$8:K29)/(A29-3) -> 0.18801623 | M29: =SUM($G$8:G29) -> 6211.7205 | N29: =M29/J29 -> 4.6405659
A30: 26 | C30: May | D30: 8650 | E30: =(D29*$E$1+D28*$F$1+D27*$G$1)/SUM($E$1:$G$1) -> 7786.7831 | G30: =D30-E30 -> 863.21694 | H30: =ABS(G30) -> 863.21694 | I30: =SUMSQ($G$8:G30)/(A30-3) -> 3343594.5 | J30: =SUM($H$8:H30)/(A30-3) -> 1317.9021 | K30: =H30/D30 -> 0.099793866 | L30: =SUM($K$8:K30)/(A30-3) -> 0.18418048 | M30: =SUM($G$8:G30) -> 7074.9375 | N30: =M30/J30 -> 5.3683331
A31: 27 | C31: June | D31: 9960 | E31: =(D30*$E$1+D29*$F$1+D28*$G$1)/SUM($E$1:$G$1) -> 8600.7432 | G31: =D31-E31 -> 1359.2568 | H31: =ABS(G31) -> 1359.2568 | I31: =SUMSQ($G$8:G31)/(A31-3) -> 3281260.5 | J31: =SUM($H$8:H31)/(A31-3) -> 1319.6252 | K31: =H31/D31 -> 0.13647157 | L31: =SUM($K$8:K31)/(A31-3) -> 0.18219261 | M31: =SUM($G$8:G31) -> 8434.1943 | N31: =M31/J31 -> 6.3913558
A32: 28 | C32: July | D32: 7152 | E32: =(D31*$E$1+D30*$F$1+D29*$G$1)/SUM($E$1:$G$1) -> 9087.3864 | G32: =D32-E32 -> -1935.3864 | H32: =ABS(G32) -> 1935.3864 | I32: =SUMSQ($G$8:G32)/(A32-3) -> 3299838.9 | J32: =SUM($H$8:H32)/(A32-3) -> 1344.2557 | K32: =H32/D32 -> 0.27060771 | L32: =SUM($K$8:K32)/(A32-3) -> 0.18572921 | M32: =SUM($G$8:G32) -> 6498.8079 | N32: =M32/J32 -> 4.8345029
A33: 29 | C33: August | D33: 7322 | E33: =(D32*$E$1+D31*$F$1+D30*$G$1)/SUM($E$1:$G$1) -> 7828.9421 | G33: =D33-E33 -> -506.94212 | H33: =ABS(G33) -> 506.94212 | I33: =SUMSQ($G$8:G33)/(A33-3) -> 3182806.3 | J33: =SUM($H$8:H33)/(A33-3) -> 1312.0513 | K33: =H33/D33 -> 0.069235471 | L33: =SUM($K$8:K33)/(A33-3) -> 0.18124868 | M33: =SUM($G$8:G33) -> 5991.8658 | N33: =M33/J33 -> 4.5667923
A34: 30 | C34: September | D34: 9239 | E34: =(D33*$E$1+D32*$F$1+D31*$G$1)/SUM($E$1:$G$1) -> 8514.105 | G34: =D34-E34 -> 724.89499 | H34: =ABS(G34) -> 724.89499 | I34: =SUMSQ($G$8:G34)/(A34-3) -> 3084386.5 | J34: =SUM($H$8:H34)/(A34-3) -> 1290.3048 | K34: =H34/D34 -> 0.07846033 | L34: =SUM($K$8:K34)/(A34-3) -> 0.17744171 | M34: =SUM($G$8:G34) -> 6716.7608 | N34: =M34/J34 -> 5.2055615
A35: 31 | C35: October | D35: 14123 | E35: =(D34*$E$1+D33*$F$1+D32*$G$1)/SUM($E$1:$G$1) -> 8295.8904 | G35: =D35-E35 -> 5827.1096 | H35: =ABS(G35) -> 5827.1096 | I35: =SUMSQ($G$8:G35)/(A35-3) -> 4186915.8 | J35: =SUM($H$8:H35)/(A35-3) -> 1452.3335 | K35: =H35/D35 -> 0.41259715 | L35: =SUM($K$8:K35)/(A35-3) -> 0.18584012 | M35: =SUM($G$8:G35) -> 12543.87 | N35: =M35/J35 -> 8.6370453
A36: 32 | C36: November | D36: 9566 | E36: =(D35*$E$1+D34*$F$1+D33*$G$1)/SUM($E$1:$G$1) -> 11049.647 | G36: =D36-E36 -> -1483.6466 | H36: =ABS(G36) -> 1483.6466 | I36: =SUMSQ($G$8:G36)/(A36-3) -> 4118443.1 | J36: =SUM($H$8:H36)/(A36-3) -> 1453.4133 | K36: =H36/D36 -> 0.15509582 | L36: =SUM($K$8:K36)/(A36-3) -> 0.18477997 | M36: =SUM($G$8:G36) -> 11060.224 | N36: =M36/J36 -> 7.6098271
A37: 33 | C37: December | D37: 7341 | E37: =(D36*$E$1+D35*$F$1+D34*$G$1)/SUM($E$1:$G$1) -> 9418.2296 | G37: =D37-E37 -> -2077.2296 | H37: =ABS(G37) -> 2077.2296 | I37: =SUMSQ($G$8:G37)/(A37-3) -> 4124991.1 | J37: =SUM($H$8:H37)/(A37-3) -> 1474.2072 | K37: =H37/D37 -> 0.28296276 | L37: =SUM($K$8:K37)/(A37-3) -> 0.18805273 | M37: =SUM($G$8:G37) -> 8982.9942 | N37: =M37/J37 -> 6.0934409
A38: 34 | B38: 2006 | C38: January | D38: 9404 | E38: =(D37*$E$1+D36*$F$1+D35*$G$1)/SUM($E$1:$G$1) -> 10405.767 | G38: =D38-E38 -> -1001.7673 | H38: =ABS(G38) -> 1001.7673 | I38: =SUMSQ($G$8:G38)/(A38-3) -> 4024299.1 | J38: =SUM($H$8:H38)/(A38-3) -> 1458.9672 | K38: =H38/D38 -> 0.10652566 | L38: =SUM($K$8:K38)/(A38-3) -> 0.18542282 | M38: =SUM($G$8:G38) -> 7981.2269 | N38: =M38/J38 -> 5.4704637
A39: 35 | C39: February | D39: 8613 | E39: =(D38*$E$1+D37*$F$1+D36*$G$1)/SUM($E$1:$G$1) -> 9477.2074 | G39: =D39-E39 -> -864.20736 | H39: =ABS(G39) -> 864.20736 | I39: =SUMSQ($G$8:G39)/(A39-3) -> 3921878.9 | J39: =SUM($H$8:H39)/(A39-3) -> 1440.3809 | K39: =H39/D39 -> 0.10033755 | L39: =SUM($K$8:K39)/(A39-3) -> 0.18276391 | M39: =SUM($G$8:G39) -> 7117.0195 | N39: =M39/J39 -> 4.9410676
A40: 36 | C40: March | D40: 9425 | E40: =(D39*$E$1+D38*$F$1+D37*$G$1)/SUM($E$1:$G$1) -> 8038.1867 | G40: =D40-E40 -> 1386.8133 | H40: =ABS(G40) -> 1386.8133 | I40: =SUMSQ($G$8:G40)/(A40-3) -> 3861314.4 | J40: =SUM($H$8:H40)/(A40-3) -> 1438.7577 | K40: =H40/D40 -> 0.147142 | L40: =SUM($K$8:K40)/(A40-3) -> 0.18168446 | M40: =SUM($G$8:G40) -> 8503.8328 | N40: =M40/J40 -> 5.9105387
A41: 37 | C41: April | D41: 10905 | E41: =(D40*$E$1+D39*$F$1+D38*$G$1)/SUM($E$1:$G$1) -> 9415.5102 | G41: =D41-E41 -> 1489.4898 | H41: =ABS(G41) -> 1489.4898 | I41: =SUMSQ($G$8:G41)/(A41-3) -> 3812998.7 | J41: =SUM($H$8:H41)/(A41-3) -> 1440.2498 | K41: =H41/D41 -> 0.13658779 | L41: =SUM($K$8:K41)/(A41-3) -> 0.18035808 | M41: =SUM($G$8:G41) -> 9993.3227 | N41: =M41/J41 -> 6.9386039
...

Sheet WMA (4m)
D1: Weights are | E1: 0.42389702 | F1: 0 | G1: 0.19851691 | H1: 0.37758607 | J1: =E1+F1+G1+H1 -> 1
E2: Last month | F2: 2mon ago | G2: 3mon ago | H2: 4mon ago
A4: #Month | B4: Year | C4: Month | D4: Actual Demand | E4: 4 Month Weighted MovAver | G4: Forecast error | H4: Absolute value | I4: MSE | J4: MAD | K4: APE | L4: MAPE | M4: Bias | N4: TS
A5: 1 | B5: 2003 | C5: April | D5: 4698
A6: 2 | C6: May | D6: 4605
A7: 3 | C7: June | D7: 4859
A8: 4 | C8: July | D8: 4136
A9: 5 | C9: August | D9: 3872 | E9: =($E$1*D8+$F$1*D7+$G$1*D6+$H$1*D5)/SUM($E$1:$H$1) -> 4441.3078 | G9: =D9-E9 -> -569.3078 | H9: =ABS(G9) -> 569.3078 | I9: =SUMSQ($G$9:G9)/(A9-4) -> 324111.37 | J9: =SUM($H$9:H9)/(A9-4) -> 569.3078 | K9: =H9/D9 -> 0.14703197 | L9: =SUM($K$9:K9)/(A9-4) -> 0.14703197 | M9: =SUM($G$9:G9) -> -569.3078 | N9: =M9/J9 -> -1
A10: 6 | C10: September | D10: 5938 | E10: =($E$1*D9+$F$1*D8+$G$1*D7+$H$1*D6)/SUM($E$1:$H$1) -> 4344.7068 | G10: =D10-E10 -> 1593.2932 | H10: =ABS(G10) -> 1593.2932 | I10: =SUMSQ($G$9:G10)/(A10-4) -> 1431347.3 | J10: =SUM($H$9:H10)/(A10-4) -> 1081.3005 | K10: =H10/D10 -> 0.26832153 | L10: =SUM($K$9:K10)/(A10-4) -> 0.20767675 | M10: =SUM($G$9:G10) -> 1023.9854 | N10: =M10/J10 -> 0.9469943
A11: 7 | C11: October | D11: 8790 | E11: =($E$1*D10+$F$1*D9+$G$1*D8+$H$1*D7)/SUM($E$1:$H$1) -> 5172.8572 | G11: =D11-E11 -> 3617.1428 | H11: =ABS(G11) -> 3617.1428 | I11: =SUMSQ($G$9:G11)/(A11-4) -> 5315472.3 | J11: =SUM($H$9:H11)/(A11-4) -> 1926.5813 | K11: =H11/D11 -> 0.41150658 | L11: =SUM($K$9:K11)/(A11-4) -> 0.27562003 | M11: =SUM($G$9:G11) -> 4641.1283 | N11: =M11/J11 -> 2.4089969
A12: 8 | C12: November | D12: 6825 | E12: =($E$1*D11+$F$1*D10+$G$1*D9+$H$1*D8)/SUM($E$1:$H$1) -> 6056.4083 | G12: =D12-E12 -> 768.59172 | H12: =ABS(G12) -> 768.59172 | I12: =SUMSQ($G$9:G12)/(A12-4) -> 4134287.6 | J12: =SUM($H$9:H12)/(A12-4) -> 1637.0839 | K12: =H12/D12 -> 0.11261417 | L12: =SUM($K$9:K12)/(A12-4) -> 0.23486856 | M12: =SUM($G$9:G12) -> 5409.72 | N12: =M12/J12 -> 3.3044855
A13: 9 | C13: December | D13: 4858 | E13: =($E$1*D12+$F$1*D11+$G$1*D10+$H$1*D9)/SUM($E$1:$H$1) -> 5533.9038 | G13: =D13-E13 -> -675.90384 | H13: =ABS(G13) -> 675.90384 | I13: =SUMSQ($G$9:G13)/(A13-4) -> 3398799.2 | J13: =SUM($H$9:H13)/(A13-4) -> 1444.8479 | K13: =H13/D13 -> 0.13913212 | L13: =SUM($K$9:K13)/(A13-4) -> 0.21572127 | M13: =SUM($G$9:G13) -> 4733.8161 | N13: =M13/J13 -> 3.2763422
A14: 10 | B14: 2004 | C14: January | D14: 5907 | E14: =($E$1*D13+$F$1*D12+$G$1*D11+$H$1*D10)/SUM($E$1:$H$1) -> 6046.3614 | G14: =D14-E14 -> -139.36144 | H14: =ABS(G14) -> 139.36144 | I14: =SUMSQ($G$9:G14)/(A14-4) -> 2835569.6 | J14: =SUM($H$9:H14)/(A14-4) -> 1227.2668 | K14: =H14/D14 -> 0.023592591 | L14: =SUM($K$9:K14)/(A14-4) -> 0.18369983 | M14: =SUM($G$9:G14) -> 4594.4547 | N14: =M14/J14 -> 3.7436478
A15: 11 | C15: February | D15: 6386 | E15: =($E$1*D14+$F$1*D13+$G$1*D12+$H$1*D11)/SUM($E$1:$H$1) -> 7177.8192 | G15: =D15-E15 -> -791.81916 | H15: =ABS(G15) -> 791.81916 | I15: =SUMSQ($G$9:G15)/(A15-4) -> 2520056.5 | J15: =SUM($H$9:H15)/(A15-4) -> 1165.06 | K15: =H15/D15 -> 0.12399298 | L15: =SUM($K$9:K15)/(A15-4) -> 0.17517028 | M15: =SUM($G$9:G15) -> 3802.6355 | N15: =M15/J15 -> 3.2638967
A16: 12 | C16: March | D16: 9085 | E16: =($E$1*D15+$F$1*D14+$G$1*D13+$H$1*D12)/SUM($E$1:$H$1) -> 6248.4265 | G16: =D16-E16 -> 2836.5735 | H16: =ABS(G16) -> 2836.5735 | I16: =SUMSQ($G$9:G16)/(A16-4) -> 3210818.1 | J16: =SUM($H$9:H16)/(A16-4) -> 1373.9992 | K16: =H16/D16 -> 0.31222604 | L16: =SUM($K$9:K16)/(A16-4) -> 0.19230225 | M16: =SUM($G$9:G16) -> 6639.2091 | N16: =M16/J16 -> 4.8320327
A17: 13 | C17: April | D17: 6492 | E17: =($E$1*D16+$F$1*D15+$G$1*D14+$H$1*D13)/SUM($E$1:$H$1) -> 6858.057 | G17: =D17-E17 -> -366.05695 | H17: =ABS(G17) -> 366.05695 | I17: =SUMSQ($G$9:G17)/(A17-4) -> 2868949.2 | J17: =SUM($H$9:H17)/(A17-4) -> 1262.0056 | K17: =H17/D17 -> 0.056385852 | L17: =SUM($K$9:K17)/(A17-4) -> 0.17720043 | M17: =SUM($G$9:G17) -> 6273.1521 | N17: =M17/J17 -> 4.9707799
A18: 14 | C18: May | D18: 6832 | E18: =($E$1*D17+$F$1*D16+$G$1*D15+$H$1*D14)/SUM($E$1:$H$1) -> 6250.0694 | G18: =D18-E18 -> 581.93064 | H18: =ABS(G18) -> 581.93064 | I18: =SUMSQ($G$9:G18)/(A18-4) -> 2615918.6 | J18: =SUM($H$9:H18)/(A18-4) -> 1193.9981 | K18: =H18/D18 -> 0.085177202 | L18: =SUM($K$9:K18)/(A18-4) -> 0.1679981 | M18: =SUM($G$9:G18) -> 6855.0828 | N18: =M18/J18 -> 5.7412844
A19: 15 | C19: June | D19: 8867 | E19: =($E$1*D18+$F$1*D17+$G$1*D16+$H$1*D15)/SUM($E$1:$H$1) -> 7110.8552 | G19: =D19-E19 -> 1756.1448 | H19: =ABS(G19) -> 1756.1448 | I19: =SUMSQ($G$9:G19)/(A19-4) -> 2658475.5 | J19: =SUM($H$9:H19)/(A19-4) -> 1245.1024 | K19: =H19/D19 -> 0.198054 | L19: =SUM($K$9:K19)/(A19-4) -> 0.17073046 | M19: =SUM($G$9:G19) -> 8611.2276 | N19: =M19/J19 -> 6.91608
A20: 16 | C20: July | D20: 4998 | E20: =($E$1*D19+$F$1*D18+$G$1*D17+$H$1*D16)/SUM($E$1:$H$1) -> 8477.8361 | G20: =D20-E20 -> -3479.8361 | H20: =ABS(G20) -> 3479.8361 | I20: =SUMSQ($G$9:G20)/(A20-4) -> 3446040.8 | J20: =SUM($H$9:H20)/(A20-4) -> 1431.3302 | K20: =H20/D20 -> 0.69624572 | L20: =SUM($K$9:K20)/(A20-4) -> 0.2145234 | M20: =SUM($G$9:G20) -> 5131.3915 | N20: =M20/J20 -> 3.5850509
A21: 17 | C21: August | D21: 5305 | E21: =($E$1*D20+$F$1*D19+$G$1*D18+$H$1*D17)/SUM($E$1:$H$1) -> 5926.1936 | G21: =D21-E21 -> -621.1936 | H21: =ABS(G21) -> 621.1936 | I21: =SUMSQ($G$9:G21)/(A21-4) -> 3210643.9 | J21: =SUM($H$9:H21)/(A21-4) -> 1369.012 | K21: =H21/D21 -> 0.11709587 | L21: =SUM($K$9:K21)/(A21-4) -> 0.20702897 | M21: =SUM($G$9:G21) -> 4510.1979 | N21: =M21/J21 -> 3.2944912
A22: 18 | C22: September | D22: 7618 | E22: =($E$1*D21+$F$1*D20+$G$1*D19+$H$1*D18)/SUM($E$1:$H$1) -> 6588.6912 | G22: =D22-E22 -> 1029.3088 | H22: =ABS(G22) -> 1029.3088 | I22: =SUMSQ($G$9:G22)/(A22-4) -> 3056989.1 | J22: =SUM($H$9:H22)/(A22-4) -> 1344.7475 | K22: =H22/D22 -> 0.13511536 | L22: =SUM($K$9:K22)/(A22-4) -> 0.20189228 | M22: =SUM($G$9:G22) -> 5539.5067 | N22: =M22/J22 -> 4.1193658
